Workbook

Sheet Language Rules Can Change
B1: 1 | C1: 2 | D1: 3 | E1: 4 | F1: 5 | G1: 6 | H1: 7 | I1: 8 | J1: 9 | K1: 10 | L1: 11 | M1: 12 | N1: 13 | O1: 14 | P1: 15 | Q1: 16 | R1: 17 | S1: 18 | T1: 19 | U1: 20 | V1: 21 | W1: 22 | X1: 23 | Y1: 24 | Z1: 25 | AA1: 26 | AB1: 27 | AC1: 28 | AD1: 29 | AE1: 30 | AF1: 31 | AG1: 32 | AH1: 33 | AI1: 34 | AJ1: 35 | AK1: 36 | AL1: 37 | AM1: 38 | AN1: 39 | AO1: 40 | AP1: 41 | AQ1: 42 | AR1: 43 | AS1: 44 | AT1: 45 | AU1: 46
A2: conversion chart final | B2: p | C2: b | D2: m | E2: w | F2: f | G2: v | H2: θ | I2: ð | J2: t | K2: s | L2: ʧ | M2: d | N2: n | O2: z | P2: ʤ | Q2: r | R2: l | S2: ʃ | T2: ʒ | U2: jə | V2: k | W2: g | X2: ŋ | Y2: h | Z2: " | AA2: æ | AB2: ɛ | AC2: ɪ | AD2: ɒ | AE2: ʌ | AF2: ʊ | AG2: eɪ | AH2: i | AI2: aɪ | AJ2: əʊ | AK2: u | AL2: ɑ | AM2: ɜ | AN2: ɔ | AO2: ju | AP2: ɔɪ | AQ2: aʊ | AR2: ə | AS2: e | AT2: ɪə | AU2: jʊə
A3: p | B3: 0.0015419035 | C3: 0.035034373 | D3: 0.057341469 | E3: 0.064843068 | F3: 0.095841208 | G3: 0.11749202 | H3: 0.1268785 | I3: 0.14513825 | J3: 0.16108627 | K3: 0.19890827 | L3: 0.21082051 | M3: 0.21825954 | N3: 0.2302602 | O3: 0.23163407 | P3: 0.23938983 | Q3: 0.24525798 | R3: 0.24650522 | S3: 0.26557425 | T3: 0.26903654 | U3: 0.26911709 | V3: 0.2881153 | W3: 0.29390286 | X3: 0.29956027 | Y3: 0.30060715 | Z3: 1 | AA3: 1 | AB3: 1 | AC3: 1 | AD3: 1 | AE3: 1 | AF3: 1 | AG3: 1 | AH3: 1 | AI3: 1 | AJ3: 1 | AK3: 1 | AL3: 1 | AM3: 1 | AN3: 1 | AO3: 1 | AP3: 1 | AQ3: 1 | AR3: 1 | AS3: 1 | AT3: 1 | AU3: 1
A4: b | B4: 0.0010498906 | C4: 0.041592481 | D4: 0.068715739 | E4: 0.077796415 | F4: 0.11473332 | G4: 0.1409416 | H4: 0.15230393 | I4: 0.17525746 | J4: 0.19456252 | K4: 0.24210689 | L4: 0.25616615 | M4: 0.26551744 | N4: 0.27968106 | O4: 0.28124017 | P4: 0.29062852 | Q4: 0.29861982 | R4: 0.3001296 | S4: 0.32321265 | T4: 0.32792762 | U4: 0.32807388 | V4: 0.35107119 | W4: 0.35895276 | X4: 0.36408897 | Y4: 0.36503941 | Z4: 1 | AA4: 1 | AB4: 1 | AC4: 1 | AD4: 1 | AE4: 1 | AF4: 1 | AG4: 1 | AH4: 1 | AI4: 1 | AJ4: 1 | AK4: 1 | AL4: 1 | AM4: 1 | AN4: 1 | AO4: 1 | AP4: 1 | AQ4: 1 | AR4: 1 | AS4: 1 | AT4: 1 | AU4: 1
A5: m | B5: 0.00075365178 | C5: 0.029986605 | D5: 0.06475467 | E5: 0.076212897 | F5: 0.12356063 | G5: 0.1566309 | H5: 0.17119575 | I5: 0.20061883 | J5: 0.21453861 | K5: 0.26024733 | L5: 0.27376377 | M5: 0.28025672 | N5: 0.29911071 | O5: 0.30105931 | P5: 0.31234164 | Q5: 0.32258533 | R5: 0.32476257 | S5: 0.35250235 | T5: 0.35854626 | U5: 0.35868687 | V5: 0.37526892 | W5: 0.38032043 | X5: 0.3877273 | Y5: 0.38955477 | Z5: 1 | AA5: 1 | AB5: 1 | AC5: 1 | AD5: 1 | AE5: 1 | AF5: 1 | AG5: 1 | AH5: 1 | AI5: 1 | AJ5: 1 | AK5: 1 | AL5: 1 | AM5: 1 | AN5: 1 | AO5: 1 | AP5: 1 | AQ5: 1 | AR5: 1 | AS5: 1 | AT5: 1 | AU5: 1
A6: w | B6: 0.00035469368 | C6: 0.01405155 | D6: 0.030087302 | E6: 0.060046322 | F6: 0.099042313 | G6: 0.1267116 | H6: 0.13870733 | I6: 0.16294042 | J6: 0.16973417 | K6: 0.20598596 | L6: 0.22653781 | M6: 0.22982868 | N6: 0.23903063 | O6: 0.24067667 | P6: 0.25678319 | Q6: 0.28209354 | R6: 0.28727388 | S6: 0.31164371 | T6: 0.31662152 | U6: 0.31708475 | V6: 0.32315458 | W6: 0.32592823 | X6: 0.3286395 | Y6: 0.32964292 | Z6: 1 | AA6: 1 | AB6: 1 | AC6: 1 | AD6: 1 | AE6: 1 | AF6: 1 | AG6: 1 | AH6: 1 | AI6: 1 | AJ6: 1 | AK6: 1 | AL6: 1 | AM6: 1 | AN6: 1 | AO6: 1 | AP6: 1 | AQ6: 1 | AR6: 1 | AS6: 1 | AT6: 1 | AU6: 1
A7: f | B7: 0.00037118235 | C7: 0.014480803 | D7: 0.031262011 | E7: 0.041137805 | F7: 0.11401066 | G7: 0.16490909 | H7: 0.1868775 | I7: 0.23125684 | J7: 0.24325423 | K7: 0.31329183 | L7: 0.33479908 | M7: 0.34039532 | N7: 0.35664549 | O7: 0.35974609 | P7: 0.37724963 | Q7: 0.39159674 | R7: 0.39472432 | S7: 0.43776015 | T7: 0.44622513 | U7: 0.44646752 | V7: 0.46075951 | W7: 0.46511339 | X7: 0.47149733 | Y7: 0.47385997 | Z7: 1 | AA7: 1 | AB7: 1 | AC7: 1 | AD7: 1 | AE7: 1 | AF7: 1 | AG7: 1 | AH7: 1 | AI7: 1 | AJ7: 1 | AK7: 1 | AL7: 1 | AM7: 1 | AN7: 1 | AO7: 1 | AP7: 1 | AQ7: 1 | AR7: 1 | AS7: 1 | AT7: 1 | AU7: 1
A8: v | B8: 0.00025350148 | C8: 0.010042718 | D8: 0.021503557 | E8: 0.033494206 | F8: 0.083263214 | G8: 0.1450613 | H8: 0.17185322 | I8: 0.22573618 | J8: 0.24030276 | K8: 0.32400989 | L8: 0.35012281 | M8: 0.3571788 | N8: 0.37690886 | O8: 0.38067344 | P8: 0.40192529 | Q8: 0.42001473 | R8: 0.42371715 | S8: 0.47596889 | T8: 0.48664191 | U8: 0.48697298 | V8: 0.50432554 | W8: 0.51027256 | X8: 0.51802359 | Y8: 0.52089218 | Z8: 1 | AA8: 1 | AB8: 1 | AC8: 1 | AD8: 1 | AE8: 1 | AF8: 1 | AG8: 1 | AH8: 1 | AI8: 1 | AJ8: 1 | AK8: 1 | AL8: 1 | AM8: 1 | AN8: 1 | AO8: 1 | AP8: 1 | AQ8: 1 | AR8: 1 | AS8: 1 | AT8: 1 | AU8: 1
A9: θ | B9: 0.00023262531 | C9: 0.0069699222 | D9: 0.014982893 | E9: 0.019698551 | F9: 0.053799167 | G9: 0.096330866 | H9: 0.12911163 | I9: 0.19533345 | J9: 0.21315613 | K9: 0.31557445 | L9: 0.34702522 | M9: 0.35565845 | N9: 0.3797988 | O9: 0.38433291 | P9: 0.41033522 | Q9: 0.43246823 | R9: 0.43717248 | S9: 0.50110414 | T9: 0.51416292 | U9: 0.51456799 | V9: 0.53845333 | W9: 0.54572969 | X9: 0.55639878 | Y9: 0.56034732 | Z9: 1 | AA9: 1 | AB9: 1 | AC9: 1 | AD9: 1 | AE9: 1 | AF9: 1 | AG9: 1 | AH9: 1 | AI9: 1 | AJ9: 1 | AK9: 1 | AL9: 1 | AM9: 1 | AN9: 1 | AO9: 1 | AP9: 1 | AQ9: 1 | AR9: 1 | AS9: 1 | AT9: 1 | AU9: 1
A10: ð | B10: 0.00027930349 | C10: 0.0048294733 | D10: 0.010241195 | E10: 0.013426011 | F10: 0.036456551 | G10: 0.06505353 | H10: 0.087192681 | I10: 0.16670246 | J10: 0.18776704 | K10: 0.31128541 | L10: 0.34904704 | M10: 0.35941259 | N10: 0.38794403 | O10: 0.39338794 | P10: 0.42412001 | Q10: 0.45069419 | R10: 0.45634239 | S10: 0.53190309 | T10: 0.54758221 | U10: 0.54803818 | V10: 0.5767163 | W10: 0.58654477 | X10: 0.59935471 | Y10: 0.60409555 | Z10: 1 | AA10: 1 | AB10: 1 | AC10: 1 | AD10: 1 | AE10: 1 | AF10: 1 | AG10: 1 | AH10: 1 | AI10: 1 | AJ10: 1 | AK10: 1 | AL10: 1 | AM10: 1 | AN10: 1 | AO10: 1 | AP10: 1 | AQ10: 1 | AR10: 1 | AS10: 1 | AT10: 1 | AU10: 1
A11: t | B11: 0.00022466324 | C11: 0.0067313625 | D11: 0.011084387 | E11: 0.012602472 | F11: 0.023188225 | G11: 0.036332534 | H11: 0.046463342 | I11: 0.082278282 | J11: 0.13606783 | K11: 0.23498068 | L11: 0.26535498 | M11: 0.29141041 | N11: 0.33221009 | O11: 0.33658901 | P11: 0.36170133 | Q11: 0.3830768 | R11: 0.38762004 | S11: 0.44936351 | T11: 0.46197532 | U11: 0.46236653 | V11: 0.53156996 | W11: 0.55440873 | X11: 0.57158193 | Y11: 0.57539532 | Z11: 1 | AA11: 1 | AB11: 1 | AC11: 1 | AD11: 1 | AE11: 1 | AF11: 1 | AG11: 1 | AH11: 1 | AI11: 1 | AJ11: 1 | AK11: 1 | AL11: 1 | AM11: 1 | AN11: 1 | AO11: 1 | AP11: 1 | AQ11: 1 | AR11: 1 | AS11: 1 | AT11: 1 | AU11: 1
A12: s | B12: 0.00025374279 | C12: 0.0043874998 | D12: 0.0080748472 | E12: 0.010164492 | F12: 0.026105735 | G12: 0.04559066 | H12: 0.060608417 | I12: 0.11478345 | J12: 0.14029923 | K12: 0.28991853 | L12: 0.33586385 | M12: 0.34822358 | N12: 0.38278406 | O12: 0.38940778 | P12: 0.42663391 | Q12: 0.45832058 | R12: 0.46516231 | S12: 0.5566899 | T12: 0.57538546 | U12: 0.57592397 | V12: 0.60849099 | W12: 0.62039634 | X12: 0.63494337 | Y12: 0.64032709 | Z12: 1 | AA12: 1 | AB12: 1 | AC12: 1 | AD12: 1 | AE12: 1 | AF12: 1 | AG12: 1 | AH12: 1 | AI12: 1 | AJ12: 1 | AK12: 1 | AL12: 1 | AM12: 1 | AN12: 1 | AO12: 1 | AP12: 1 | AQ12: 1 | AR12: 1 | AS12: 1 | AT12: 1 | AU12: 1
A13: ʧ | B13: 0.00020788062 | C13: 0.003469061 | D13: 0.0063780625 | E13: 0.009538598 | F13: 0.022598576 | G13: 0.038815127 | H13: 0.051118533 | I13: 0.09530456 | J13: 0.11620855 | K13: 0.23878525 | L13: 0.30570265 | M13: 0.31598918 | N13: 0.3443031 | O13: 0.34970551 | P13: 0.40416583 | Q13: 0.4503161 | R13: 0.46012509 | S13: 0.53510974 | T13: 0.55066933 | U13: 0.55148381 | V13: 0.57994329 | W13: 0.58969684 | X13: 0.60240912 | Y13: 0.60711382 | Z13: 1 | AA13: 1 | AB13: 1 | AC13: 1 | AD13: 1 | AE13: 1 | AF13: 1 | AG13: 1 | AH13: 1 | AI13: 1 | AJ13: 1 | AK13: 1 | AL13: 1 | AM13: 1 | AN13: 1 | AO13: 1 | AP13: 1 | AQ13: 1 | AR13: 1 | AS13: 1 | AT13: 1 | AU13: 1
A14: d | B14: 0.00028895826 | C14: 0.0049964152 | D14: 0.0080290933 | E14: 0.0091273954 | F14: 0.016502309 | G14: 0.026011934 | H14: 0.033341355 | I14: 0.059663985 | J14: 0.098579567 | K14: 0.17014088 | L14: 0.19246485 | M14: 0.22597692 | N14: 0.27868709 | O14: 0.28431918 | P14: 0.31611358 | Q14: 0.34360636 | R14: 0.3494498 | S14: 0.42762242 | T14: 0.44384354 | U14: 0.44445678 | V14: 0.53346511 | W14: 0.56396978 | X14: 0.58550548 | Y14: 0.5904102 | Z14: 1 | AA14: 1 | AB14: 1 | AC14: 1 | AD14: 1 | AE14: 1 | AF14: 1 | AG14: 1 | AH14: 1 | AI14: 1 | AJ14: 1 | AK14: 1 | AL14: 1 | AM14: 1 | AN14: 1 | AO14: 1 | AP14: 1 | AQ14: 1 | AR14: 1 | AS14: 1 | AT14: 1 | AU14: 1
... A47: jʊə | B47: 0 | C47: 0 | D47: 0 | E47: 0 | F47: 0 | G47: 0 | H47: 0 | I47: 0 | J47: 0 | K47: 0 | L47: 0 | M47: 0 | N47: 0 | O47: 0 | P47: 0 | Q47: 0 | R47: 0 | S47: 0 | T47: 0 | U47: 0 | V47: 0 | W47: 0 | X47: 0 | Y47: 0 | Z47: 0.50373807 | AA47: 0.51104529 | AB47: 0.51242131 | AC47: 0.51346775 | AD47: 0.53034804 | AE47: 0.5369792 | AF47: 0.54051852 | AG47: 0.55238271 | AH47: 0.58958317 | AI47: 0.59711602 | AJ47: 0.62392474 | AK47: 0.64468519 | AL47: 0.67640709 | AM47: 0.70842787 | AN47: 0.73930538 | AO47: 0.7755099 | AP47: 0.79923294 | AQ47: 0.88204278 | AR47: 0.88935051 | AS47: 0.95413166 | AT47: 0.99643371 | AU47: 1
A51: Short | B51: æ | C51: ɛ | D51: ɪ | E51: ɒ | F51: ʌ | G51: ʊ
A52: Long | B52: eɪ | C52: i | D52: aɪ | E52: əʊ | G52: u
A53: R | B53: ɑ | C53: ɜ | D53: ɔ
A54: Other | B54: ju | C54: ɔɪ | D54: aʊ | E54: ə | F54: e | G54: ɪə | H54: jʊə
B57: 0.0625 | C57: 0.125 | D57: 0.1875 | E57: 0.25 | F57: 0.3125 | G57: 0.375 | H57: 0.4375 | I57: 0.5 | J57: 0.5625 | K57: 0.625 | L57: 0.6875 | M57: 0.75 | N57: 0.8125 | O57: 0.875 | P57: 0.9375 | Q57: 1 | V57: 0.14285714 | W57: 0.28571429 | X57: 0.42857143 | Y57: 0.57142857 | Z57: 0.71428571 | AA57: 0.85714286 | AB57: 1
B58: 1 | C58: 0.9375 | D58: 0.875 | E58: 0.8125 | F58: 0.75 | G58: 0.6875 | H58: 0.625 | I58: 0.5625 | J58: 0.5 | K58: 0.4375 | L58: 0.375 | M58: 0.3125 | N58: 0.25 | O58: 0.1875 | P58: 0.125 | Q58: 0.0625 | V58: 1 | W58: 0.85714286 | X58: 0.71428571 | Y58: 0.57142857 | Z58: 0.42857143 | AA58: 0.28571429 | AB58: 0.14285714
B59: Bilabial | D59: Labio-dental | F59: Inter-dental | H59: Alveolar | J59: Post-alveolar | L59: Palatal | N59: Velar | P59: Glottal | U59: Short | V59: æ | W59: ɛ | X59: ɪ | Y59: ɒ | Z59: ʌ | AA59: ʊ | AC59: 0.25 | AD59: 1
A60: Stops | B60: p | C60: b | H60: t | I60: d | N60: k | O60: g | R60: 0.16666667 | S60: 1 | U60: Long | V60: eɪ | W60: i | X60: aɪ | Y60: əʊ | AA60: u | AC60: 0.5 | AD60: 0.75
A61: Nasal | C61: m | I61: n | O61: ŋ | R61: 0.33333333 | S61: 0.83333333 | U61: R | V61: ɑ | W61: ɜ | X61: ɔ | AC61: 0.75 | AD61: 0.5
A62: Fricative | D62: f | E62: v | F62: θ | G62: ð | H62: s | I62: z | J62: ʃ | K62: ʒ | P62: h | R62: 0.5 | S62: 0.66666667 | U62: Other | V62: ju | W62: ɔɪ | X62: aʊ | Y62: ə | Z62: e | AA62: ɪə | AB62: jʊə | AC62: 1 | AD62: 0.25
A63: Affricates | H63: ʧ | I63: ʤ | R63: 0.66666667 | S63: 0.5
A64: Approximants | C64: w | I64: r | M64: jə | R64: 0.83333333 | S64: 0.33333333
A65: Lateral | I65: l | R65: 1 | S65: 0.16666667
A68: 1 | B68: 0.0625 | C68: 0.125 | D68: 0.1875 | E68: 0.25 | F68: 0.3125 | G68: 0.375 | H68: 0.4375 | I68: 0.5 | J68: 0.5625 | K68: 0.625 | L68: 0.6875 | M68: 0.75 | N68: 0.8125 | O68: 0.875 | P68: 0.9375 | Q68: 1 | U68: 2 | V68: 0.14285714 | W68: 0.28571429 | X68: 0.42857143 | Y68: 0.57142857 | Z68: 0.71428571 | AA68: 0.85714286 | AB68: 1
A69: 2 | B69: 1 | C69: 0.9375 | D69: 0.875 | E69: 0.8125 | F69: 0.75 | G69: 0.6875 | H69: 0.625 | I69: 0.5625 | J69: 0.5 | K69: 0.4375 | L69: 0.375 | M69: 0.3125 | N69: 0.25 | O69: 0.1875 | P69: 0.125 | Q69: 0.0625 | U69: 1 | V69: 1 | W69: 0.85714286 | X69: 0.71428571 | Y69: 0.57142857 | Z69: 0.42857143 | AA69: 0.28571429 | AB69: 0.14285714
B70: Bilabial | D70: Labio-dental | F70: Inter-dental | H70: Alveolar | J70: Post-alveolar | L70: Palatal | N70: Velar | P70: Glottal | U70: Short | V70: 0.25 | W70: 0.21428571 | X70: 0.17857143 | Y70: 0.14285714 | Z70: 0.10714286 | AA70: 0.071428571 | AC70: 0.25 | AD70: 1
A71: Stops | B71: 0.0625 | C71: 0.125 | H71: 0.4375 | I71: 0.5 | N71: 0.8125 | O71: 0.875 | R71: 0.16666667 | S71: 1 | U71: Long | V71: 0.5 | W71: 0.42857143 | X71: 0.35714286 | Y71: 0.28571429 | AA71: 0.14285714 | AC71: 0.5 | AD71: 0.75
A72: Nasal | C72: 0.10416667 | I72: 0.41666667 | O72: 0.72916667 | R72: 0.33333333 | S72: 0.83333333 | U72: R | V72: 0.75 | W72: 0.64285714 | X72: 0.53571429 | AC72: 0.75 | AD72: 0.5
A73: Fricative | D73: 0.125 | E73: 0.16666667 | F73: 0.20833333 | G73: 0.25 | H73: 0.29166667 | I73: 0.33333333 | J73: 0.375 | K73: 0.41666667 | P73: 0.625 | R73: 0.5 | S73: 0.66666667 | U73: Other | V73: 1 | W73: 0.85714286 | X73: 0.71428571 | Y73: 0.57142857 | Z73: 0.42857143 | AA73: 0.28571429 | AB73: 0.14285714 | AC73: 1 | AD73: 0.25
A74: Affricates | H74: 0.21875 | I74: 0.25 | R74: 0.66666667 | S74: 0.5
A75: Approximants | C75: 0.041666667 | I75: 0.16666667 | M75: 0.25 | R75: 0.83333333 | S75: 0.33333333
A76: Lateral | I76: 0.083333333 | R76: 1 | S76: 0.16666667
A81: 1 | B81: 2 | C81: 3 | D81: 4 | E81: 5 | F81: 6 | G81: 7 | H81: 8 | I81: 9 | J81: 10 | K81: 11 | L81: 12 | M81: 13 | N81: 14 | O81: 15 | P81: 16 | Q81: 17 | R81: 18 | S81: 19 | T81: 20 | U81: 21 | V81: 22 | W81: 23 | X81: 24 | Y81: 25
A82: conversion chart 1 | B82: p | C82: b | D82: m | E82: w | F82: f | G82: v | H82: θ | I82: ð | J82: t | K82: s | L82: ʧ | M82: d | N82: n | O82: z | P82: ʤ | Q82: r | R82: l | S82: ʃ | T82: ʒ | U82: jə | V82: k | W82: g | X82: ŋ | Y82: h | Z82: æ | AA82: ɛ | AB82: ɪ | AC82: ɒ | AD82: ʌ | AE82: ʊ | AF82: eɪ | AG82: i | AH82: aɪ | AI82: əʊ | AJ82: u | AK82: ɑ | AL82: ɜ | AM82: ɔ | AN82: ju | AO82: ɔɪ | AP82: aʊ | AQ82: ə | AR82: e | AS82: ɪə | AT82: jʊə | AU82: 1
A83: p | B83: 0 | C83: 1 | D83: 2 | E83: 5 | F83: 4 | G83: 5 | H83: 6 | I83: 7 | J83: 6 | K83: 7 | L83: 8 | M83: 7 | N83: 8 | O83: 9 | P83: 10 | Q83: 11 | R83: 12 | S83: 10 | T83: 11 | U83: 15 | V83: 12 | W83: 13 | X83: 14 | Y83: 16 | Z83: 100 | AA83: 100 | AB83: 100 | AC83: 100 | AD83: 100 | AE83: 100 | AF83: 100 | AG83: 100 | AH83: 100 | AI83: 100 | AJ83: 100 | AK83: 100 | AL83: 100 | AM83: 100 | AN83: 100 | AO83: 100 | AP83: 100 | AQ83: 100 | AR83: 100 | AS83: 100 | AT83: 100 | AU83: 2
...

Sheet Language Rules Dont Touch
B1: 1 | C1: 2 | D1: 3 | E1: 4 | F1: 5 | G1: 6 | H1: 7 | I1: 8 | J1: 9 | K1: 10 | L1: 11 | M1: 12 | N1: 13 | O1: 14 | P1: 15 | Q1: 16 | R1: 17 | S1: 18 | T1: 19 | U1: 20 | V1: 21 | W1: 22 | X1: 23 | Y1: 24 | Z1: 25 | AA1: 26 | AB1: 27 | AC1: 28 | AD1: 29 | AE1: 30 | AF1: 31 | AG1: 32 | AH1: 33 | AI1: 34 | AJ1: 35 | AK1: 36 | AL1: 37 | AM1: 38 | AN1: 39 | AO1: 40 | AP1: 41 | AQ1: 42 | AR1: 43 | AS1: 44 | AT1: 45 | AU1: 46
A2: conversion chart final | B2: p | C2: b | D2: m | E2: w | F2: f | G2: v | H2: θ | I2: ð | J2: t | K2: s | L2: ʧ | M2: d | N2: n | O2: z | P2: ʤ | Q2: r | R2: l | S2: ʃ | T2: ʒ | U2: jə | V2: k | W2: g | X2: ŋ | Y2: h | Z2: " | AA2: æ | AB2: ɛ | AC2: ɪ | AD2: ɒ | AE2: ʌ | AF2: ʊ | AG2: eɪ | AH2: i | AI2: aɪ | AJ2: əʊ | AK2: u | AL2: ɑ | AM2: ɜ | AN2: ɔ | AO2: ju | AP2: ɔɪ | AQ2: aʊ | AR2: ə | AS2: e | AT2: ɪə | AU2: jʊə
A3: p | B3: =IF(B263=0,1,SUM($B263:B263)) -> 0.013112396 | C3: =IF(C263=0,1,SUM($B263:C263)) -> 0.036485489 | D3: =IF(D263=0,1,SUM($B263:D263)) -> 0.069542935 | E3: =IF(E263=0,1,SUM($B263:E263)) -> 0.084576733 | F3: =IF(F263=0,1,SUM($B263:F263)) -> 0.098715663 | G3: =IF(G263=0,1,SUM($B263:G263)) -> 0.13463923 | H3: =IF(H263=0,1,SUM($B263:H263)) -> 0.15162126 | I3: =IF(I263=0,1,SUM($B263:I263)) -> 0.18892746 | ... AU3: =IF(AU263=0,1,SUM($B263:AU263)) -> 1
A4: b | B4: =IF(B264=0,1,SUM($B264:B264)) -> 0.0087448061 | C4: =IF(C264=0,1,SUM($B264:C264)) -> 0.036456418 | D4: =IF(D264=0,1,SUM($B264:D264)) -> 0.075824967 | E4: =IF(E264=0,1,SUM($B264:E264)) -> 0.093649342 | F4: =IF(F264=0,1,SUM($B264:F264)) -> 0.11015082 | G4: =IF(G264=0,1,SUM($B264:G264)) -> 0.15274252 | H4: =IF(H264=0,1,SUM($B264:H264)) -> 0.17287676 | I4: =IF(I264=0,1,SUM($B264:I264)) -> 0.21880895 | ... AU4: =IF(AU264=0,1,SUM($B264:AU264)) -> 1
A5: m | B5: =IF(B265=0,1,SUM($B265:B265)) -> 0.0060230888 | C5: =IF(C265=0,1,SUM($B265:C265)) -> 0.025194998 | D5: =IF(D265=0,1,SUM($B265:D265)) -> 0.073615631 | E5: =IF(E265=0,1,SUM($B265:E265)) -> 0.095195854 | F5: =IF(F265=0,1,SUM($B265:F265)) -> 0.11549154 | G5: =IF(G265=0,1,SUM($B265:G265)) -> 0.16705792 | H5: =IF(H265=0,1,SUM($B265:H265)) -> 0.19182167 | I5: =IF(I265=0,1,SUM($B265:I265)) -> 0.24831512 | ... AU5: =IF(AU265=0,1,SUM($B265:AU265)) -> 1
A6: w | B6: =IF(B266=0,1,SUM($B266:B266)) -> 0.0026411118 | C6: =IF(C266=0,1,SUM($B266:C266)) -> 0.01101059 | D6: =IF(D266=0,1,SUM($B266:D266)) -> 0.031818289 | E6: =IF(E266=0,1,SUM($B266:E266)) -> 0.08438986 | F6: =IF(F266=0,1,SUM($B266:F266)) -> 0.09996419 | G6: =IF(G266=0,1,SUM($B266:G266)) -> 0.14016286 | H6: =IF(H266=0,1,SUM($B266:H266)) -> 0.15916584 | I6: =IF(I266=0,1,SUM($B266:I266)) -> 0.2025173 | ... AU6: =IF(AU266=0,1,SUM($B266:AU266)) -> 1
A7: f | B7: =IF(B267=0,1,SUM($B267:B267)) -> 0.0027309776 | C7: =IF(C267=0,1,SUM($B267:C267)) -> 0.011250011 | D7: =IF(D267=0,1,SUM($B267:D267)) -> 0.032765707 | E7: =IF(E267=0,1,SUM($B267:E267)) -> 0.04988922 | F7: =IF(F267=0,1,SUM($B267:F267)) -> 0.078646824 | G7: =IF(G267=0,1,SUM($B267:G267)) -> 0.15171286 | H7: =IF(H267=0,1,SUM($B267:H267)) -> 0.18609962 | I7: =IF(I267=0,1,SUM($B267:I267)) -> 0.26454604 | ... AU7: =IF(AU267=0,1,SUM($B267:AU267)) -> 1
A8: v | B8: =IF(B268=0,1,SUM($B268:B268)) -> 0.0017514851 | C8: =IF(C268=0,1,SUM($B268:C268)) -> 0.0073018056 | D8: =IF(D268=0,1,SUM($B268:D268)) -> 0.021100682 | E8: =IF(E268=0,1,SUM($B268:E268)) -> 0.040624226 | F8: =IF(F268=0,1,SUM($B268:F268)) -> 0.059067627 | G8: =IF(G268=0,1,SUM($B268:G268)) -> 0.1423746 | H8: =IF(H268=0,1,SUM($B268:H268)) -> 0.18175604 | I8: =IF(I268=0,1,SUM($B268:I268)) -> 0.2711975 | ... AU8: =IF(AU268=0,1,SUM($B268:AU268)) -> 1
A9: θ | B9: =IF(B269=0,1,SUM($B269:B269)) -> 0.001545772 | C9: =IF(C269=0,1,SUM($B269:C269)) -> 0.0052195955 | D9: =IF(D269=0,1,SUM($B269:D269)) -> 0.014498215 | E9: =IF(E269=0,1,SUM($B269:E269)) -> 0.021882711 | F9: =IF(F269=0,1,SUM($B269:F269)) -> 0.034036362 | G9: =IF(G269=0,1,SUM($B269:G269)) -> 0.089178242 | H9: =IF(H269=0,1,SUM($B269:H269)) -> 0.13551966 | I9: =IF(I269=0,1,SUM($B269:I269)) -> 0.24123818 | ... AU9: =IF(AU269=0,1,SUM($B269:AU269)) -> 1
A10: ð | B10: =IF(B270=0,1,SUM($B270:B270)) -> 0.0017910165 | C10: =IF(C270=0,1,SUM($B270:C270)) -> 0.004185407 | D10: =IF(D270=0,1,SUM($B270:D270)) -> 0.010232687 | E10: =IF(E270=0,1,SUM($B270:E270)) -> 0.015045484 | F10: =IF(F270=0,1,SUM($B270:F270)) -> 0.022966546 | G10: =IF(G270=0,1,SUM($B270:G270)) -> 0.05874518 | H10: =IF(H270=0,1,SUM($B270:H270)) -> 0.088947895 | I10: =IF(I270=0,1,SUM($B270:I270)) -> 0.2114392 | ... AU10: =IF(AU270=0,1,SUM($B270:AU270)) -> 1
A11: t | B11: =IF(B271=0,1,SUM($B271:B271)) -> 0.0016592917 | C11: =IF(C271=0,1,SUM($B271:C271)) -> 0.0056029168 | D11: =IF(D271=0,1,SUM($B271:D271)) -> 0.011205434 | E11: =IF(E271=0,1,SUM($B271:E271)) -> 0.013847703 | F11: =IF(F271=0,1,SUM($B271:F271)) -> 0.018041124 | G11: =IF(G271=0,1,SUM($B271:G271)) -> 0.036982384 | H11: =IF(H271=0,1,SUM($B271:H271)) -> 0.052900681 | I11: =IF(I271=0,1,SUM($B271:I271)) -> 0.11645081 | ... AU11: =IF(AU271=0,1,SUM($B271:AU271)) -> 1
A12: s | B12: =IF(B272=0,1,SUM($B272:B272)) -> 0.0015962864 | C12: =IF(C272=0,1,SUM($B272:C272)) -> 0.0037303445 | D12: =IF(D272=0,1,SUM($B272:D272)) -> 0.007772682 | E12: =IF(E272=0,1,SUM($B272:E272)) -> 0.010870669 | F12: =IF(F272=0,1,SUM($B272:F272)) -> 0.016249593 | G12: =IF(G272=0,1,SUM($B272:G272)) -> 0.040166018 | H12: =IF(H272=0,1,SUM($B272:H272)) -> 0.060265459 | I12: =IF(I272=0,1,SUM($B272:I272)) -> 0.14214545 | ... AU12: =IF(AU272=0,1,SUM($B272:AU272)) -> 1
A13: ʧ | B13: =IF(B273=0,1,SUM($B273:B273)) -> 0.0011992546 | C13: =IF(C273=0,1,SUM($B273:C273)) -> 0.0027431447 | D13: =IF(D273=0,1,SUM($B273:D273)) -> 0.0056675848 | E13: =IF(E273=0,1,SUM($B273:E273)) -> 0.0099644139 | F13: =IF(F273=0,1,SUM($B273:F273)) -> 0.01400548 | G13: =IF(G273=0,1,SUM($B273:G273)) -> 0.032258564 | H13: =IF(H273=0,1,SUM($B273:H273)) -> 0.047358829 | I13: =IF(I273=0,1,SUM($B273:I273)) -> 0.10860005 | ... AU13: =IF(AU273=0,1,SUM($B273:AU273)) -> 1
A14: d | B14: =IF(B274=0,1,SUM($B274:B274)) -> 0.0020678131 | C14: =IF(C274=0,1,SUM($B274:C274)) -> 0.0048322499 | D14: =IF(D274=0,1,SUM($B274:D274)) -> 0.0086140961 | E14: =IF(E274=0,1,SUM($B274:E274)) -> 0.010466296 | F14: =IF(F274=0,1,SUM($B274:F274)) -> 0.013296966 | G14: =IF(G274=0,1,SUM($B274:G274)) -> 0.026574577 | H14: =IF(H274=0,1,SUM($B274:H274)) -> 0.037733124 | I14: =IF(I274=0,1,SUM($B274:I274)) -> 0.082988161 | ... AU14: =IF(AU274=0,1,SUM($B274:AU274)) -> 1
... A26: h | B26: =IF(B286=0,1,SUM($B286:B286)) -> 0.00066074394 | C26: =IF(C286=0,1,SUM($B286:C286)) -> 0.00085704203 | D26: =IF(D286=0,1,SUM($B286:D286)) -> 0.0016006986 | E26: =IF(E286=0,1,SUM($B286:E286)) -> 0.0019952636 | F26: =IF(F286=0,1,SUM($B286:F286)) -> 0.0028301916 | G26: =IF(G286=0,1,SUM($B286:G286)) -> 0.0066014762 | H26: =IF(H286=0,1,SUM($B286:H286)) -> 0.010167051 | I26: =IF(I286=0,1,SUM($B286:I286)) -> 0.024627735 | ... AU26: =IF(AU286=0,1,SUM($B286:AU286)) -> 1
A27: æ | B27: =IF(B287=0,0,SUM($B287:B287)) -> 0 | C27: =IF(C287=0,0,SUM($B287:C287)) -> 0 | D27: =IF(D287=0,0,SUM($B287:D287)) -> 0 | E27: =IF(E287=0,0,SUM($B287:E287)) -> 0 | F27: =IF(F287=0,0,SUM($B287:F287)) -> 0 | G27: =IF(G287=0,0,SUM($B287:G287)) -> 0 | H27: =IF(H287=0,0,SUM($B287:H287)) -> 0 | I27: =IF(I287=0,0,SUM($B287:I287)) -> 0 | ... AU27: =IF(AU287=0,0,SUM($B287:AU287)) -> 1
A28: ɛ | B28: =IF(B288=0,0,SUM($B288:B288)) -> 0 | C28: =IF(C288=0,0,SUM($B288:C288)) -> 0 | D28: =IF(D288=0,0,SUM($B288:D288)) -> 0 | E28: =IF(E288=0,0,SUM($B288:E288)) -> 0 | F28: =IF(F288=0,0,SUM($B288:F288)) -> 0 | G28: =IF(G288=0,0,SUM($B288:G288)) -> 0 | H28: =IF(H288=0,0,SUM($B288:H288)) -> 0 | I28: =IF(I288=0,0,SUM($B288:I288)) -> 0 | ... AU28: =IF(AU288=0,0,SUM($B288:AU288)) -> 1
A29: ɪ | B29: =IF(B289=0,0,SUM($B289:B289)) -> 0 | C29: =IF(C289=0,0,SUM($B289:C289)) -> 0 | D29: =IF(D289=0,0,SUM($B289:D289)) -> 0 | E29: =IF(E289=0,0,SUM($B289:E289)) -> 0 | F29: =IF(F289=0,0,SUM($B289:F289)) -> 0 | G29: =IF(G289=0,0,SUM($B289:G289)) -> 0 | H29: =IF(H289=0,0,SUM($B289:H289)) -> 0 | I29: =IF(I289=0,0,SUM($B289:I289)) -> 0 | ... AU29: =IF(AU289=0,0,SUM($B289:AU289)) -> 1
A30: ɒ | B30: =IF(B290=0,0,SUM($B290:B290)) -> 0 | C30: =IF(C290=0,0,SUM($B290:C290)) -> 0 | D30: =IF(D290=0,0,SUM($B290:D290)) -> 0 | E30: =IF(E290=0,0,SUM($B290:E290)) -> 0 | F30: =IF(F290=0,0,SUM($B290:F290)) -> 0 | G30: =IF(G290=0,0,SUM($B290:G290)) -> 0 | H30: =IF(H290=0,0,SUM($B290:H290)) -> 0 | I30: =IF(I290=0,0,SUM($B290:I290)) -> 0 | ... AU30: =IF(AU290=0,0,SUM($B290:AU290)) -> 1
A31: ʌ | B31: =IF(B291=0,0,SUM($B291:B291)) -> 0 | C31: =IF(C291=0,0,SUM($B291:C291)) -> 0 | D31: =IF(D291=0,0,SUM($B291:D291)) -> 0 | E31: =IF(E291=0,0,SUM($B291:E291)) -> 0 | F31: =IF(F291=0,0,SUM($B291:F291)) -> 0 | G31: =IF(G291=0,0,SUM($B291:G291)) -> 0 | H31: =IF(H291=0,0,SUM($B291:H291)) -> 0 | I31: =IF(I291=0,0,SUM($B291:I291)) -> 0 | ... AU31: =IF(AU291=0,0,SUM($B291:AU291)) -> 1
A32: ʊ | B32: =IF(B292=0,0,SUM($B292:B292)) -> 0 | C32: =IF(C292=0,0,SUM($B292:C292)) -> 0 | D32: =IF(D292=0,0,SUM($B292:D292)) -> 0 | E32: =IF(E292=0,0,SUM($B292:E292)) -> 0 | F32: =IF(F292=0,0,SUM($B292:F292)) -> 0 | G32: =IF(G292=0,0,SUM($B292:G292)) -> 0 | H32: =IF(H292=0,0,SUM($B292:H292)) -> 0 | I32: =IF(I292=0,0,SUM($B292:I292)) -> 0 | ... AU32: =IF(AU292=0,0,SUM($B292:AU292)) -> 1
A33: eɪ | B33: =IF(B293=0,0,SUM($B293:B293)) -> 0 | C33: =IF(C293=0,0,SUM($B293:C293)) -> 0 | D33: =IF(D293=0,0,SUM($B293:D293)) -> 0 | E33: =IF(E293=0,0,SUM($B293:E293)) -> 0 | F33: =IF(F293=0,0,SUM($B293:F293)) -> 0 | G33: =IF(G293=0,0,SUM($B293:G293)) -> 0 | H33: =IF(H293=0,0,SUM($B293:H293)) -> 0 | I33: =IF(I293=0,0,SUM($B293:I293)) -> 0 | ... AU33: =IF(AU293=0,0,SUM($B293:AU293)) -> 1
A34: i | B34: =IF(B294=0,0,SUM($B294:B294)) -> 0 | C34: =IF(C294=0,0,SUM($B294:C294)) -> 0 | D34: =IF(D294=0,0,SUM($B294:D294)) -> 0 | E34: =IF(E294=0,0,SUM($B294:E294)) -> 0 | F34: =IF(F294=0,0,SUM($B294:F294)) -> 0 | G34: =IF(G294=0,0,SUM($B294:G294)) -> 0 | H34: =IF(H294=0,0,SUM($B294:H294)) -> 0 | I34: =IF(I294=0,0,SUM($B294:I294)) -> 0 | ... AU34: =IF(AU294=0,0,SUM($B294:AU294)) -> 1
A35: aɪ | B35: =IF(B295=0,0,SUM($B295:B295)) -> 0 | C35: =IF(C295=0,0,SUM($B295:C295)) -> 0 | D35: =IF(D295=0,0,SUM($B295:D295)) -> 0 | E35: =IF(E295=0,0,SUM($B295:E295)) -> 0 | F35: =IF(F295=0,0,SUM($B295:F295)) -> 0 | G35: =IF(G295=0,0,SUM($B295:G295)) -> 0 | H35: =IF(H295=0,0,SUM($B295:H295)) -> 0 | I35: =IF(I295=0,0,SUM($B295:I295)) -> 0 | ... AU35: =IF(AU295=0,0,SUM($B295:AU295)) -> 1
A36: əʊ | B36: =IF(B296=0,0,SUM($B296:B296)) -> 0 | C36: =IF(C296=0,0,SUM($B296:C296)) -> 0 | D36: =IF(D296=0,0,SUM($B296:D296)) -> 0 | E36: =IF(E296=0,0,SUM($B296:E296)) -> 0 | F36: =IF(F296=0,0,SUM($B296:F296)) -> 0 | G36: =IF(G296=0,0,SUM($B296:G296)) -> 0 | H36: =IF(H296=0,0,SUM($B296:H296)) -> 0 | I36: =IF(I296=0,0,SUM($B296:I296)) -> 0 | ... AU36: =IF(AU296=0,0,SUM($B296:AU296)) -> 1
A37: u | B37: =IF(B297=0,0,SUM($B297:B297)) -> 0 | C37: =IF(C297=0,0,SUM($B297:C297)) -> 0 | D37: =IF(D297=0,0,SUM($B297:D297)) -> 0 | E37: =IF(E297=0,0,SUM($B297:E297)) -> 0 | F37: =IF(F297=0,0,SUM($B297:F297)) -> 0 | G37: =IF(G297=0,0,SUM($B297:G297)) -> 0 | H37: =IF(H297=0,0,SUM($B297:H297)) -> 0 | I37: =IF(I297=0,0,SUM($B297:I297)) -> 0 | ... AU37: =IF(AU297=0,0,SUM($B297:AU297)) -> 1
A38: ɑ | B38: =IF(B298=0,0,SUM($B298:B298)) -> 0 | C38: =IF(C298=0,0,SUM($B298:C298)) -> 0 | D38: =IF(D298=0,0,SUM($B298:D298)) -> 0 | E38: =IF(E298=0,0,SUM($B298:E298)) -> 0 | F38: =IF(F298=0,0,SUM($B298:F298)) -> 0 | G38: =IF(G298=0,0,SUM($B298:G298)) -> 0 | H38: =IF(H298=0,0,SUM($B298:H298)) -> 0 | I38: =IF(I298=0,0,SUM($B298:I298)) -> 0 | ... AU38: =IF(AU298=0,0,SUM($B298:AU298)) -> 1
... A47: jʊə | B47: =IF(B307=0,0,SUM($B307:B307)) -> 0 | C47: =IF(C307=0,0,SUM($B307:C307)) -> 0 | D47: =IF(D307=0,0,SUM($B307:D307)) -> 0 | E47: =IF(E307=0,0,SUM($B307:E307)) -> 0 | F47: =IF(F307=0,0,SUM($B307:F307)) -> 0 | G47: =IF(G307=0,0,SUM($B307:G307)) -> 0 | H47: =IF(H307=0,0,SUM($B307:H307)) -> 0 | I47: =IF(I307=0,0,SUM($B307:I307)) -> 0 | ... AU47: =IF(AU307=0,0,SUM($B307:AU307)) -> 1
A51: Short | B51: æ | C51: ɛ | D51: ɪ | E51: ɒ | F51: ʌ | G51: ʊ
A52: Long | B52: eɪ | C52: i | D52: aɪ | E52: əʊ | G52: u
A53: R | B53: ɑ | C53: ɜ | D53: ɔ
A54: Other | B54: ju | C54: ɔɪ | D54: aʊ | E54: ə | F54: e | G54: ɪə | H54: jʊə
B57: 0.0625 | C57: 0.125 | D57: 0.1875 | E57: 0.25 | F57: 0.3125 | G57: 0.375 | H57: 0.4375 | I57: 0.5 | J57: 0.5625 | K57: 0.625 | L57: 0.6875 | M57: 0.75 | N57: 0.8125 | O57: 0.875 | P57: 0.9375 | Q57: 1 | V57: 0.14285714 | W57: 0.28571429 | X57: 0.42857143 | Y57: 0.57142857 | Z57: 0.71428571 | AA57: 0.85714286 | AB57: 1
B58: 1 | C58: 0.9375 | D58: 0.875 | E58: 0.8125 | F58: 0.75 | G58: 0.6875 | H58: 0.625 | I58: 0.5625 | J58: 0.5 | K58: 0.4375 | L58: 0.375 | M58: 0.3125 | N58: 0.25 | O58: 0.1875 | P58: 0.125 | Q58: 0.0625 | V58: 1 | W58: 0.85714286 | X58: 0.71428571 | Y58: 0.57142857 | Z58: 0.42857143 | AA58: 0.28571429 | AB58: 0.14285714
B59: Bilabial | D59: Labio-dental | F59: Inter-dental | H59: Alveolar | J59: Post-alveolar | L59: Palatal | N59: Velar | P59: Glottal | U59: Short | V59: æ | W59: ɛ | X59: ɪ | Y59: ɒ | Z59: ʌ | AA59: ʊ | AC59: =1/4 -> 0.25 | AD59: =4/4 -> 1
A60: Stops | B60: p | C60: b | H60: t | I60: d | N60: k | O60: g | R60: 0.16666667 | S60: 1 | U60: Long | V60: eɪ | W60: i | X60: aɪ | Y60: əʊ | AA60: u | AC60: =2/4 -> 0.5 | AD60: =3/4 -> 0.75
A61: Nasal | C61: m | I61: n | O61: ŋ | R61: 0.33333333 | S61: 0.83333333 | U61: R | V61: ɑ | W61: ɜ | X61: ɔ | AC61: =3/4 -> 0.75 | AD61: =2/4 -> 0.5
A62: Fricative | D62: f | E62: v | F62: θ | G62: ð | H62: s | I62: z | J62: ʃ | K62: ʒ | P62: h | R62: 0.5 | S62: 0.66666667 | U62: Other | V62: ju | W62: ɔɪ | X62: aʊ | Y62: ə | Z62: e | AA62: ɪə | AB62: jʊə | AC62: =4/4 -> 1 | AD62: =1/4 -> 0.25
A63: Affricates | H63: ʧ | I63: ʤ | R63: 0.66666667 | S63: 0.5
A64: Approximants | C64: w | I64: r | M64: jə | R64: 0.83333333 | S64: 0.33333333
...

Sheet All Words All Languages
A1: Word | B1: Pronunciation | C1: New Words Vocal | D1: New Words Spelling | E1: Type | H1: Pronunciation | I1: 1 | J1: New Words Vocal | K1: New Words Spelling | N1: New Words Spelling
A2: a | B2: eɪ/ | C2: "///////////// | D2: " | E2: OPERATIONS | F2: 1 | H2: =B2 -> eɪ/ | L2: 1 | N2: oy
A3: able | B3: eɪ/b/ə/l/ | C3: "/"/ɜ/r////////// | D3: ""ourwr | E3: QUALITIES | F3: 2 | H3: =B3 -> eɪ/b/ə/l/ | N3: ier"ir"
A4: about | B4: ə/b/aʊ/t/ | C4: ɪə/"/"/"////////// | D4: ier""" | E4: OPERATIONS | F4: 3 | H4: =B4 -> ə/b/aʊ/t/ | L4: =L2+1 -> 2 | N4: ""owdd
A5: account | B5: ə/k/aʊ/n/t/ | C5: "/r/"/d/"///////// | D5: "wr"dd" | E5: THINGS | F5: 4 | H5: =B5 -> ə/k/aʊ/n/t/ | N5: ""ou"ze
A6: acid | B6: æ/s/ə/d/ | C6: "/"/ɪə/jə////////// | D6: ""eeri | E6: QUALITIES | F6: 5 | H6: =B6 -> æ/s/ə/d/ | L6: =L4+1 -> 3 | N6: a"u"
A7: across | B7: ə/k/r/ɔ/s/ | C7: "/z/z/ɔ/"///////// | D7: "zzzzaw" | E7: OPERATIONS | F7: 6 | H7: =B7 -> ə/k/r/ɔ/s/ | N7: """owti
A8: act | B8: æ/k/t/ | C8: "/"/r/////////// | D8: ""rh | E8: THINGS | F8: 7 | H8: =B8 -> æ/k/t/ | L8: =L6+1 -> 4 | N8: "gh"
A9: addition | B9: ə/d/ɪ/ʃ/ə/n/ | C9: e/ʤ/ə/ʃ/u/"//////// | D9: eardiisoeu" | E9: THINGS | F9: 8 | H9: =B9 -> ə/d/ɪ/ʃ/ə/n/ | N9: "z"rh"f
A10: adjustment | B10: ə/ʤ/ʌ/s/t/m/ə/n/t/ | C10: "/ʤ/"/"/"/"/"/"/"///// | D10: "dge""""""" | E10: THINGS | F10: 9 | H10: =B10 -> ə/ʤ/ʌ/s/t/m/ə/n/t/ | L10: =L8+1 -> 5 | N10: ossopn"n"tic
A11: advertisement | B11: ə/d/v/ɜ/r/t/ə/z/m/ə/n/t/ | C11: ɪə/ʤ/m/aɪ/ʃ/ʧ/ʌ/"/ʒ/ə/"/"// | D11: eerdimnaishteoo"si"" | E11: THINGS | F11: 10 | H11: =B11 -> ə/d/v/ɜ/r/t/ə/z/m/ə/n/t/ | N11: you"ftoi"""sez""se
A12: after | B12: æ/f/t/ə/r/ | C12: "/"/"/ə/r///////// | D12: """iwr | E12: OPERATIONS | F12: 11 | H12: =B12 -> æ/f/t/ə/r/ | L12: =L10+1 -> 6 | N12: oi""""
A13: again | B13: ə/g/ɛ/n/ | C13: ɪə/"/ɛ/ŋ////////// | D13: ear"ein | E13: OPERATIONS | F13: 12 | H13: =B13 -> ə/g/ɛ/n/ | N13: yu""te
A14: against | B14: ə/g/ɛ/n/s/t/ | C14: u/"/ju/"/r/z//////// | D14: ough"you"rhss | E14: OPERATIONS | F14: 13 | H14: =B14 -> ə/g/ɛ/n/s/t/ | L14: =L12+1 -> 7 | N14: ""ow"""
A15: agreement | B15: ə/g/r/i/m/ə/n/t/ | C15: "/ŋ/ʤ/ɪə/"/jʊə/"/"////// | D15: "ngdiere"our"" | E15: THINGS | F15: 14 | H15: =B15 -> ə/g/r/i/m/ə/n/t/ | N15: eiz"oux"th"
A16: air | B16: ɛ/r/ | C16: "/r//////////// | D16: "" | E16: THINGS | F16: 15 | H16: =B16 -> ɛ/r/ | L16: =L14+1 -> 8 | N16: eigh"
A17: all | B17: ɔ/l/ | C17: ɪə/ʤ//////////// | D17: erej | E17: OPERATIONS | F17: 16 | H17: =B17 -> ɔ/l/ | N17: ""
A18: almost | B18: ɔ/l/m/o/ʊ/s/t/ | C18: ɪə/ʤ/"//"/θ/ʤ/////// | D18: eredge""thg | E18: OPERATIONS | F18: 17 | H18: =B18 -> ɔ/l/m/o/ʊ/s/t/ | L18: =L16+1 -> 9 | N18: ow""oof"
A19: among | B19: ə/m/ʌ/ŋ/ | C19: e/"/ɛ/"////////// | D19: eir"ae" | E19: OPERATIONS | F19: 18 | H19: =B19 -> ə/m/ʌ/ŋ/ | N19: oi"""
A20: amount | B20: ə/m/aʊ/n/t/ | C20: ɪə/"/jʊə/"/r///////// | D20: ere"our"r | E20: THINGS | F20: 19 | H20: =B20 -> ə/m/aʊ/n/t/ | L20: =L18+1 -> 10 | N20: ""oughssti
A21: amusement | B21: ə/m/ju/z/m/ə/n/t/ | C21: "/"/ju/jə/w/ɪə/"/ʤ////// | D21: ""ieu"oeer"di | E21: THINGS | F21: 20 | H21: =B21 -> ə/m/ju/z/m/ə/n/t/ | N21: ou"youcedge"""
A22: and | B22: æ/n/d/ | C22: "/"/ŋ/////////// | D22: ""n | E22: OPERATIONS | F22: 21 | H22: =B22 -> æ/n/d/ | L22: =L20+1 -> 11 | N22: ""si
A23: angle | B23: æ/ŋ/g/ə/l/ | C23: i/"/ʤ/i/l///////// | D23: ey"diill | E23: THINGS | F23: 22 | H23: =B23 -> æ/ŋ/g/ə/l/ | N23: ""gueeusi
A24: angry | B24: æ/ŋ/g/r/i/ | C24: "/jə/"/"/ɛ///////// | D24: "i""ai | E24: QUALITIES | F24: 23 | H24: =B24 -> æ/ŋ/g/r/i/ | L24: =L22+1 -> 12 | N24: "gn""oy
A25: animal | B25: æ/n/ə/m/ə/l/ | C25: "/"/jʊə/"/ɪə/z//////// | D25: ""ure"ierzz | E25: THINGS | F25: 24 | H25: =B25 -> æ/n/ə/m/ə/l/ | N25: """phydge
A26: answer | B26: æ/n/s/ə/r/ | C26: əʊ/"/jə/"/"///////// | D26: ow"i"" | E26: THINGS | F26: 25 | H26: =B26 -> æ/n/s/ə/r/ | L26: =L24+1 -> 13 | N26: eau""eu"
A27: ant | B27: æ/n/t/ | C27: "/"/r/////////// | D27: ""wr | E27: THINGS | F27: 26 | H27: =B27 -> æ/n/t/ | N27: ""d
A28: any | B28: ɛ/n/i/ | C28: ɪə/h/u/////////// | D28: earhoeu | E28: OPERATIONS | F28: 27 | H28: =B28 -> ɛ/n/i/ | L28: =L26+1 -> 14 | N28: areftei
A29: apparatus | B29: æ/p/ə/r/æ/t/ə/s/ | C29: ɔ/"/ʊ/"/"/f/e/"////// | D29: aw"o""pheir" | E29: THINGS | F29: 28 | H29: =B29 -> æ/p/ə/r/æ/t/ə/s/ | N29: "ftou"isffiess
A30: apple | B30: æ/p/ə/l/ | C30: "/"/"/r////////// | D30: """rr | E30: THINGS | F30: 29 | H30: =B30 -> æ/p/ə/l/ | L30: =L28+1 -> 15 | N30: "bb"rr
A31: approval | B31: ə/p/r/u/v/ə/l/ | C31: jʊə/"/r/e/ʤ/ə/ʤ/////// | D31: ure""eregeerdi | E31: THINGS | F31: 30 | H31: =B31 -> ə/p/r/u/v/ə/l/ | N31: uy"x""u"
A32: arch | B32: ɑ/r/ʧ/ | C32: jʊə/ʤ/ʃ/////////// | D32: uredgech | E32: THINGS | F32: 31 | H32: =B32 -> ɑ/r/ʧ/ | L32: =L30+1 -> 16 | N32: """
A33: argument | B33: ɑ/r/g/jə/m/ə/n/t/ | C33: "/"/h/"/"/jʊə/ʤ/"////// | D33: ""h""uredi" | E33: THINGS | F33: 32 | H33: =B33 -> ɑ/r/g/jə/m/ə/n/t/ | N33: """"x""z
A34: arm | B34: ɑ/r/m/ | C34: i/"/r/////////// | D34: ie"r | E34: THINGS | F34: 33 | H34: =B34 -> ɑ/r/m/ | L34: =L32+1 -> 17 | N34: ""v
A35: army | B35: ɑ/r/m/i/ | C35: ɔ/"/"/ɪə////////// | D35: oor""ere | E35: THINGS | F35: 34 | H35: =B35 -> ɑ/r/m/i/ | N35: "sc"o
A36: art | B36: ɑ/r/t/ | C36: "/r/"/////////// | D36: "rh" | E36: THINGS | F36: 35 | H36: =B36 -> ɑ/r/t/ | L36: =L34+1 -> 18 | N36: ieu""
A37: as | B37: æ/z/ | C37: "/r//////////// | D37: "" | E37: OPERATIONS | F37: 36 | H37: =B37 -> æ/z/ | N37: ""
A38: at | B38: æ/t/ | C38: e/"//////////// | D38: ayer" | E38: OPERATIONS | F38: 37 | H38: =B38 -> æ/t/ | L38: =L36+1 -> 19 | N38: "ss
A39: attack | B39: ə/t/æ/k/ | C39: ɪə/θ/ɪ/"////////// | D39: eerthie" | E39: THINGS | F39: 38 | H39: =B39 -> ə/t/æ/k/ | N39: ""you"
A40: attempt | B40: ə/t/ɛ/m/p/t/ | C40: ɪə/r/"/"/"/t//////// | D40: ierr"""t | E40: THINGS | F40: 39 | H40: =B40 -> ə/t/ɛ/m/p/t/ | L40: =L38+1 -> 20 | N40: ough"hov""
...

Sheet Verse-True
A1: 793 | F1: 1 | G1: 2 | H1: 3 | I1: 4 | J1: 5 | K1: 6 | L1: 7 | M1: 8 | N1: 9 | O1: 10 | P1: 11 | Q1: 12 | R1: 13 | S1: 14 | U1: =A1+1 -> 794 | Z1: 1 | AA1: 2 | AB1: 3 | AC1: 4 | AD1: 5 | AE1: 6 | AF1: 7 | AG1: 8 | AH1: 9 | AI1: 10 | AJ1: 11 | AK1: 12 | AL1: 13 | AM1: 14
A2: {=INDEX('All Words All Languages'!$A$2:$A$853,'Verse-True'!A1)} -> verse | B2: 1 | C2: =IF(B2<=A8,RANDBETWEEN(A4/(3/2),A4*(3/2)),"") -> 1 | D2: OG Pronunciation | E2: {=INDEX('All Words All Languages'!$H$2:$H$853,A1)} -> v/ɜ/r/s/ | F2: {=_xlfn.TEXTSPLIT(E2,"/")} -> v | G2: ɜ | H2: r | I2: s | U2: {=INDEX('All Words All Languages'!$A$2:$A$853,'Verse-True'!U1)} -> very | V2: 1 | W2: =IF(V2<=U8,RANDBETWEEN(U4/(3/2),U4*(3/2)),"") -> 1 | X2: OG Pronunciation | Y2: {=INDEX('All Words All Languages'!$H$2:$H$853,U1)} -> v/ɛ/r/i/ | Z2: {=_xlfn.TEXTSPLIT(Y2,"/")} -> v | AA2: ɛ | AB2: r | AC2: i
B3: 2 | C3: =IF(B3<=A8,RANDBETWEEN(A4/(3/2),A4*(3/2))+C2,"") -> 2 | F3: =MATCH(F2,'Language Rules Can Change'!$A$3:$A$47,0) -> 6 | G3: =MATCH(G2,'Language Rules Can Change'!$A$3:$A$47,0) -> 37 | H3: =MATCH(H2,'Language Rules Can Change'!$A$3:$A$47,0) -> 16 | I3: =MATCH(I2,'Language Rules Can Change'!$A$3:$A$47,0) -> 10 | J3: =MATCH(J2,'Language Rules Can Change'!$A$3:$A$47,0) -> #N/A | K3: =MATCH(K2,'Language Rules Can Change'!$A$3:$A$47,0) -> #N/A | L3: =MATCH(L2,'Language Rules Can Change'!$A$3:$A$47,0) -> #N/A | M3: =MATCH(M2,'Language Rules Can Change'!$A$3:$A$47,0) -> #N/A | ... S3: =MATCH(S2,'Language Rules Can Change'!$A$3:$A$47,0) -> #N/A | V3: 2 | W3: =IF(V3<=U8,RANDBETWEEN(U4/(3/2),U4*(3/2))+W2,"") -> 2 | Z3: =MATCH(Z2,'Language Rules Can Change'!$A$3:$A$47,0) -> 6 | AA3: =MATCH(AA2,'Language Rules Can Change'!$A$3:$A$47,0) -> 26 | AB3: =MATCH(AB2,'Language Rules Can Change'!$A$3:$A$47,0) -> 16 | AC3: =MATCH(AC2,'Language Rules Can Change'!$A$3:$A$47,0) -> 32 | AD3: =MATCH(AD2,'Language Rules Can Change'!$A$3:$A$47,0) -> #N/A | AE3: =MATCH(AE2,'Language Rules Can Change'!$A$3:$A$47,0) -> #N/A | AF3: =MATCH(AF2,'Language Rules Can Change'!$A$3:$A$47,0) -> #N/A | AG3: =MATCH(AG2,'Language Rules Can Change'!$A$3:$A$47,0) -> #N/A | ... AM3: =MATCH(AM2,'Language Rules Can Change'!$A$3:$A$47,0) -> #N/A
A4: ='All Words All Languages'!$I$1 -> 1 | B4: 3 | C4: =IF(B4<=A8,RANDBETWEEN(A4/(3/2),A4*(3/2))+C3,"") -> 3 | F4: =RAND() -> 0.15725068 | G4: =RAND() -> 0.84206995 | H4: =RAND() -> 0.25653096 | I4: =RAND() -> 0.37832126 | J4: =RAND() -> 0.68020431 | K4: =RAND() -> 0.80189063 | L4: =RAND() -> 0.78581185 | M4: =RAND() -> 0.43275442 | ... S4: =RAND() -> 0.26594858 | U4: ='All Words All Languages'!$I$1 -> 1 | V4: 3 | W4: =IF(V4<=U8,RANDBETWEEN(U4/(3/2),U4*(3/2))+W3,"") -> 3 | Z4: =RAND() -> 0.42056188 | AA4: =RAND() -> 0.075480408 | AB4: =RAND() -> 0.046872468 | AC4: =RAND() -> 0.81258163 | AD4: =RAND() -> 0.64415259 | AE4: =RAND() -> 0.41144904 | AF4: =RAND() -> 0.86563589 | AG4: =RAND() -> 0.59159676 | ... AM4: =RAND() -> 0.89490282
