Workbook

Sheet Map 1
A1: Land | B1: 0.3 | C1: 5 | D1: 1 | E1: 2 | F1: 3 | G1: 4 | H1: 5 | J1: 10 | K1: 1 | L1: 2 | M1: 3 | N1: 4 | O1: 5 | P1: 6 | Q1: 7 | R1: 8 | S1: 9 | T1: 10 | W1: 4 | X1: 1 | Y1: 2 | Z1: 3 | AA1: 4 | AC1: 8 | AD1: 1 | AE1: 2 | AF1: 3 | AG1: 4 | AH1: 5 | AI1: 6 | AJ1: 7 | AK1: 8
A2: Water | B2: =1-B1 -> 0.7 | C2: 1 | D2: =IF(RAND()<=$B$1,4,8) -> 8 | E2: =IF(RAND()<=$B$1,4,8) -> 8 | F2: =IF(RAND()<=$B$1,4,8) -> 8 | G2: =IF(RAND()<=$B$1,4,8) -> 8 | H2: =IF(RAND()<=$B$1,4,8) -> 4 | J2: 1 | K2: {=INDEX($D$2:$H$6,ROUNDUP($J2/2,0),ROUNDUP(IF(MOD(K$1+INDEX(_xlfn.TEXTSPLIT(B61,",",),0,2)+$J$1,$J$1)=0,$J$1,MOD(K$1+INDEX(_xlfn.TEXTSPLIT(B61,",",),0,2)+$J$1,$J$1))/2,0))} -> 4 | L2: {=INDEX($D$2:$H$6,ROUNDUP($J2/2,0),ROUNDUP(IF(MOD(L$1+INDEX(_xlfn.TEXTSPLIT(C61,",",),0,2)+$J$1,$J$1)=0,$J$1,MOD(L$1+INDEX(_xlfn.TEXTSPLIT(C61,",",),0,2)+$J$1,$J$1))/2,0))} -> 8 | M2: {=INDEX($D$2:$H$6,ROUNDUP($J2/2,0),ROUNDUP(IF(MOD(M$1+INDEX(_xlfn.TEXTSPLIT(D61,",",),0,2)+$J$1,$J$1)=0,$J$1,MOD(M$1+INDEX(_xlfn.TEXTSPLIT(D61,",",),0,2)+$J$1,$J$1))/2,0))} -> 8 | N2: {=INDEX($D$2:$H$6,ROUNDUP($J2/2,0),ROUNDUP(IF(MOD(N$1+INDEX(_xlfn.TEXTSPLIT(E61,",",),0,2)+$J$1,$J$1)=0,$J$1,MOD(N$1+INDEX(_xlfn.TEXTSPLIT(E61,",",),0,2)+$J$1,$J$1))/2,0))} -> 8 | O2: {=INDEX($D$2:$H$6,ROUNDUP($J2/2,0),ROUNDUP(IF(MOD(O$1+INDEX(_xlfn.TEXTSPLIT(F61,",",),0,2)+$J$1,$J$1)=0,$J$1,MOD(O$1+INDEX(_xlfn.TEXTSPLIT(F61,",",),0,2)+$J$1,$J$1))/2,0))} -> 8 | P2: {=INDEX($D$2:$H$6,ROUNDUP($J2/2,0),ROUNDUP(IF(MOD(P$1+INDEX(_xlfn.TEXTSPLIT(G61,",",),0,2)+$J$1,$J$1)=0,$J$1,MOD(P$1+INDEX(_xlfn.TEXTSPLIT(G61,",",),0,2)+$J$1,$J$1))/2,0))} -> 8 | Q2: {=INDEX($D$2:$H$6,ROUNDUP($J2/2,0),ROUNDUP(IF(MOD(Q$1+INDEX(_xlfn.TEXTSPLIT(H61,",",),0,2)+$J$1,$J$1)=0,$J$1,MOD(Q$1+INDEX(_xlfn.TEXTSPLIT(H61,",",),0,2)+$J$1,$J$1))/2,0))} -> 8 | R2: {=INDEX($D$2:$H$6,ROUNDUP($J2/2,0),ROUNDUP(IF(MOD(R$1+INDEX(_xlfn.TEXTSPLIT(I61,",",),0,2)+$J$1,$J$1)=0,$J$1,MOD(R$1+INDEX(_xlfn.TEXTSPLIT(I61,",",),0,2)+$J$1,$J$1))/2,0))} -> 4 | ... T2: {=INDEX($D$2:$H$6,ROUNDUP($J2/2,0),ROUNDUP(IF(MOD(T$1+INDEX(_xlfn.TEXTSPLIT(K61,",",),0,2)+$J$1,$J$1)=0,$J$1,MOD(T$1+INDEX(_xlfn.TEXTSPLIT(K61,",",),0,2)+$J$1,$J$1))/2,0))} -> 8 | W2: 1 | X2: =RANDBETWEEN(-3,0) -> 0 | Y2: =RANDBETWEEN(-3,0) -> -3 | Z2: =RANDBETWEEN(-3,0) -> 0 | AA2: =RANDBETWEEN(-3,0) -> -2 | AC2: 1 | AD2: {=INDEX($X$2:$AA$5,ROUNDUP($AC2/2,0),ROUNDUP(IF(MOD(AD$1+INDEX(_xlfn.TEXTSPLIT(N61,",",),0,2)+$AC$1,$AC$1)=0,$AC$1,MOD(AD$1+INDEX(_xlfn.TEXTSPLIT(N61,",",),0,2)+$AC$1,$AC$1))/2,0))} -> -2 | AE2: {=INDEX($X$2:$AA$5,ROUNDUP($AC2/2,0),ROUNDUP(IF(MOD(AE$1+INDEX(_xlfn.TEXTSPLIT(O61,",",),0,2)+$AC$1,$AC$1)=0,$AC$1,MOD(AE$1+INDEX(_xlfn.TEXTSPLIT(O61,",",),0,2)+$AC$1,$AC$1))/2,0))} -> -3 | AF2: {=INDEX($X$2:$AA$5,ROUNDUP($AC2/2,0),ROUNDUP(IF(MOD(AF$1+INDEX(_xlfn.TEXTSPLIT(P61,",",),0,2)+$AC$1,$AC$1)=0,$AC$1,MOD(AF$1+INDEX(_xlfn.TEXTSPLIT(P61,",",),0,2)+$AC$1,$AC$1))/2,0))} -> 0 | AG2: {=INDEX($X$2:$AA$5,ROUNDUP($AC2/2,0),ROUNDUP(IF(MOD(AG$1+INDEX(_xlfn.TEXTSPLIT(Q61,",",),0,2)+$AC$1,$AC$1)=0,$AC$1,MOD(AG$1+INDEX(_xlfn.TEXTSPLIT(Q61,",",),0,2)+$AC$1,$AC$1))/2,0))} -> -3 | AH2: {=INDEX($X$2:$AA$5,ROUNDUP($AC2/2,0),ROUNDUP(IF(MOD(AH$1+INDEX(_xlfn.TEXTSPLIT(R61,",",),0,2)+$AC$1,$AC$1)=0,$AC$1,MOD(AH$1+INDEX(_xlfn.TEXTSPLIT(R61,",",),0,2)+$AC$1,$AC$1))/2,0))} -> 0 | AI2: {=INDEX($X$2:$AA$5,ROUNDUP($AC2/2,0),ROUNDUP(IF(MOD(AI$1+INDEX(_xlfn.TEXTSPLIT(S61,",",),0,2)+$AC$1,$AC$1)=0,$AC$1,MOD(AI$1+INDEX(_xlfn.TEXTSPLIT(S61,",",),0,2)+$AC$1,$AC$1))/2,0))} -> -2 | AJ2: {=INDEX($X$2:$AA$5,ROUNDUP($AC2/2,0),ROUNDUP(IF(MOD(AJ$1+INDEX(_xlfn.TEXTSPLIT(T61,",",),0,2)+$AC$1,$AC$1)=0,$AC$1,MOD(AJ$1+INDEX(_xlfn.TEXTSPLIT(T61,",",),0,2)+$AC$1,$AC$1))/2,0))} -> 0 | AK2: {=INDEX($X$2:$AA$5,ROUNDUP($AC2/2,0),ROUNDUP(IF(MOD(AK$1+INDEX(_xlfn.TEXTSPLIT(U61,",",),0,2)+$AC$1,$AC$1)=0,$AC$1,MOD(AK$1+INDEX(_xlfn.TEXTSPLIT(U61,",",),0,2)+$AC$1,$AC$1))/2,0))} -> -2
C3: 2 | D3: =IF(RAND()<=$B$1,4,8) -> 8 | E3: =IF(RAND()<=$B$1,4,8) -> 8 | F3: =IF(RAND()<=$B$1,4,8) -> 4 | G3: =IF(RAND()<=$B$1,4,8) -> 8 | H3: =IF(RAND()<=$B$1,4,8) -> 8 | J3: 2 | K3: {=INDEX($D$2:$H$6,ROUNDUP(IF(MOD($J3+INDEX(_xlfn.TEXTSPLIT(B62,",",),0,1)+$J$1,$J$1)=0,$J$1,MOD($J3+INDEX(_xlfn.TEXTSPLIT(B62,",",),0,1)+$J$1,$J$1))/2,0),ROUNDUP(IF(MOD(K$1+INDEX(_xlfn.TEXTSPLIT(B62,",",),0,2)+$J$1,$J$1)=0,$J$1,MOD(K$1+INDEX(_xlfn.TEXTSPLIT(B62,",",),0,2)+$J$1,$J$1))/2,0))} -> 8 | L3: {=INDEX($D$2:$H$6,ROUNDUP(IF(MOD($J3+INDEX(_xlfn.TEXTSPLIT(C62,",",),0,1)+$J$1,$J$1)=0,$J$1,MOD($J3+INDEX(_xlfn.TEXTSPLIT(C62,",",),0,1)+$J$1,$J$1))/2,0),ROUNDUP(IF(MOD(L$1+INDEX(_xlfn.TEXTSPLIT(C62,",",),0,2)+$J$1,$J$1)=0,$J$1,MOD(L$1+INDEX(_xlfn.TEXTSPLIT(C62,",",),0,2)+$J$1,$J$1))/2,0))} -> 8 | M3: {=INDEX($D$2:$H$6,ROUNDUP(IF(MOD($J3+INDEX(_xlfn.TEXTSPLIT(D62,",",),0,1)+$J$1,$J$1)=0,$J$1,MOD($J3+INDEX(_xlfn.TEXTSPLIT(D62,",",),0,1)+$J$1,$J$1))/2,0),ROUNDUP(IF(MOD(M$1+INDEX(_xlfn.TEXTSPLIT(D62,",",),0,2)+$J$1,$J$1)=0,$J$1,MOD(M$1+INDEX(_xlfn.TEXTSPLIT(D62,",",),0,2)+$J$1,$J$1))/2,0))} -> 8 | N3: {=INDEX($D$2:$H$6,ROUNDUP(IF(MOD($J3+INDEX(_xlfn.TEXTSPLIT(E62,",",),0,1)+$J$1,$J$1)=0,$J$1,MOD($J3+INDEX(_xlfn.TEXTSPLIT(E62,",",),0,1)+$J$1,$J$1))/2,0),ROUNDUP(IF(MOD(N$1+INDEX(_xlfn.TEXTSPLIT(E62,",",),0,2)+$J$1,$J$1)=0,$J$1,MOD(N$1+INDEX(_xlfn.TEXTSPLIT(E62,",",),0,2)+$J$1,$J$1))/2,0))} -> 8 | O3: {=INDEX($D$2:$H$6,ROUNDUP(IF(MOD($J3+INDEX(_xlfn.TEXTSPLIT(F62,",",),0,1)+$J$1,$J$1)=0,$J$1,MOD($J3+INDEX(_xlfn.TEXTSPLIT(F62,",",),0,1)+$J$1,$J$1))/2,0),ROUNDUP(IF(MOD(O$1+INDEX(_xlfn.TEXTSPLIT(F62,",",),0,2)+$J$1,$J$1)=0,$J$1,MOD(O$1+INDEX(_xlfn.TEXTSPLIT(F62,",",),0,2)+$J$1,$J$1))/2,0))} -> 8 | P3: {=INDEX($D$2:$H$6,ROUNDUP(IF(MOD($J3+INDEX(_xlfn.TEXTSPLIT(G62,",",),0,1)+$J$1,$J$1)=0,$J$1,MOD($J3+INDEX(_xlfn.TEXTSPLIT(G62,",",),0,1)+$J$1,$J$1))/2,0),ROUNDUP(IF(MOD(P$1+INDEX(_xlfn.TEXTSPLIT(G62,",",),0,2)+$J$1,$J$1)=0,$J$1,MOD(P$1+INDEX(_xlfn.TEXTSPLIT(G62,",",),0,2)+$J$1,$J$1))/2,0))} -> 8 | Q3: {=INDEX($D$2:$H$6,ROUNDUP(IF(MOD($J3+INDEX(_xlfn.TEXTSPLIT(H62,",",),0,1)+$J$1,$J$1)=0,$J$1,MOD($J3+INDEX(_xlfn.TEXTSPLIT(H62,",",),0,1)+$J$1,$J$1))/2,0),ROUNDUP(IF(MOD(Q$1+INDEX(_xlfn.TEXTSPLIT(H62,",",),0,2)+$J$1,$J$1)=0,$J$1,MOD(Q$1+INDEX(_xlfn.TEXTSPLIT(H62,",",),0,2)+$J$1,$J$1))/2,0))} -> 8 | R3: {=INDEX($D$2:$H$6,ROUNDUP(IF(MOD($J3+INDEX(_xlfn.TEXTSPLIT(I62,",",),0,1)+$J$1,$J$1)=0,$J$1,MOD($J3+INDEX(_xlfn.TEXTSPLIT(I62,",",),0,1)+$J$1,$J$1))/2,0),ROUNDUP(IF(MOD(R$1+INDEX(_xlfn.TEXTSPLIT(I62,",",),0,2)+$J$1,$J$1)=0,$J$1,MOD(R$1+INDEX(_xlfn.TEXTSPLIT(I62,",",),0,2)+$J$1,$J$1))/2,0))} -> 8 | ... T3: {=INDEX($D$2:$H$6,ROUNDUP(IF(MOD($J3+INDEX(_xlfn.TEXTSPLIT(K62,",",),0,1)+$J$1,$J$1)=0,$J$1,MOD($J3+INDEX(_xlfn.TEXTSPLIT(K62,",",),0,1)+$J$1,$J$1))/2,0),ROUNDUP(IF(MOD(T$1+INDEX(_xlfn.TEXTSPLIT(K62,",",),0,2)+$J$1,$J$1)=0,$J$1,MOD(T$1+INDEX(_xlfn.TEXTSPLIT(K62,",",),0,2)+$J$1,$J$1))/2,0))} -> 4 | W3: 2 | X3: =RANDBETWEEN(-3,0) -> -2 | Y3: =RANDBETWEEN(-3,0) -> -1 | Z3: =RANDBETWEEN(-3,0) -> -1 | AA3: =RANDBETWEEN(-3,0) -> -3 | AC3: 2 | AD3: {=INDEX($X$2:$AA$5,ROUNDUP(IF(MOD($AC3+INDEX(_xlfn.TEXTSPLIT(N62,",",),0,1)+$AC$1,$AC$1)=0,$AC$1,MOD($AC3+INDEX(_xlfn.TEXTSPLIT(N62,",",),0,1)+$AC$1,$AC$1))/2,0),ROUNDUP(IF(MOD(AD$1+INDEX(_xlfn.TEXTSPLIT(N62,",",),0,2)+$AC$1,$AC$1)=0,$AC$1,MOD(AD$1+INDEX(_xlfn.TEXTSPLIT(N62,",",),0,2)+$AC$1,$AC$1))/2,0))} -> -3 | AE3: {=INDEX($X$2:$AA$5,ROUNDUP(IF(MOD($AC3+INDEX(_xlfn.TEXTSPLIT(O62,",",),0,1)+$AC$1,$AC$1)=0,$AC$1,MOD($AC3+INDEX(_xlfn.TEXTSPLIT(O62,",",),0,1)+$AC$1,$AC$1))/2,0),ROUNDUP(IF(MOD(AE$1+INDEX(_xlfn.TEXTSPLIT(O62,",",),0,2)+$AC$1,$AC$1)=0,$AC$1,MOD(AE$1+INDEX(_xlfn.TEXTSPLIT(O62,",",),0,2)+$AC$1,$AC$1))/2,0))} -> 0 | AF3: {=INDEX($X$2:$AA$5,ROUNDUP(IF(MOD($AC3+INDEX(_xlfn.TEXTSPLIT(P62,",",),0,1)+$AC$1,$AC$1)=0,$AC$1,MOD($AC3+INDEX(_xlfn.TEXTSPLIT(P62,",",),0,1)+$AC$1,$AC$1))/2,0),ROUNDUP(IF(MOD(AF$1+INDEX(_xlfn.TEXTSPLIT(P62,",",),0,2)+$AC$1,$AC$1)=0,$AC$1,MOD(AF$1+INDEX(_xlfn.TEXTSPLIT(P62,",",),0,2)+$AC$1,$AC$1))/2,0))} -> -3 | AG3: {=INDEX($X$2:$AA$5,ROUNDUP(IF(MOD($AC3+INDEX(_xlfn.TEXTSPLIT(Q62,",",),0,1)+$AC$1,$AC$1)=0,$AC$1,MOD($AC3+INDEX(_xlfn.TEXTSPLIT(Q62,",",),0,1)+$AC$1,$AC$1))/2,0),ROUNDUP(IF(MOD(AG$1+INDEX(_xlfn.TEXTSPLIT(Q62,",",),0,2)+$AC$1,$AC$1)=0,$AC$1,MOD(AG$1+INDEX(_xlfn.TEXTSPLIT(Q62,",",),0,2)+$AC$1,$AC$1))/2,0))} -> -3 | AH3: {=INDEX($X$2:$AA$5,ROUNDUP(IF(MOD($AC3+INDEX(_xlfn.TEXTSPLIT(R62,",",),0,1)+$AC$1,$AC$1)=0,$AC$1,MOD($AC3+INDEX(_xlfn.TEXTSPLIT(R62,",",),0,1)+$AC$1,$AC$1))/2,0),ROUNDUP(IF(MOD(AH$1+INDEX(_xlfn.TEXTSPLIT(R62,",",),0,2)+$AC$1,$AC$1)=0,$AC$1,MOD(AH$1+INDEX(_xlfn.TEXTSPLIT(R62,",",),0,2)+$AC$1,$AC$1))/2,0))} -> -3 | AI3: {=INDEX($X$2:$AA$5,ROUNDUP(IF(MOD($AC3+INDEX(_xlfn.TEXTSPLIT(S62,",",),0,1)+$AC$1,$AC$1)=0,$AC$1,MOD($AC3+INDEX(_xlfn.TEXTSPLIT(S62,",",),0,1)+$AC$1,$AC$1))/2,0),ROUNDUP(IF(MOD(AI$1+INDEX(_xlfn.TEXTSPLIT(S62,",",),0,2)+$AC$1,$AC$1)=0,$AC$1,MOD(AI$1+INDEX(_xlfn.TEXTSPLIT(S62,",",),0,2)+$AC$1,$AC$1))/2,0))} -> 0 | AJ3: {=INDEX($X$2:$AA$5,ROUNDUP(IF(MOD($AC3+INDEX(_xlfn.TEXTSPLIT(T62,",",),0,1)+$AC$1,$AC$1)=0,$AC$1,MOD($AC3+INDEX(_xlfn.TEXTSPLIT(T62,",",),0,1)+$AC$1,$AC$1))/2,0),ROUNDUP(IF(MOD(AJ$1+INDEX(_xlfn.TEXTSPLIT(T62,",",),0,2)+$AC$1,$AC$1)=0,$AC$1,MOD(AJ$1+INDEX(_xlfn.TEXTSPLIT(T62,",",),0,2)+$AC$1,$AC$1))/2,0))} -> -2 | AK3: {=INDEX($X$2:$AA$5,ROUNDUP(IF(MOD($AC3+INDEX(_xlfn.TEXTSPLIT(U62,",",),0,1)+$AC$1,$AC$1)=0,$AC$1,MOD($AC3+INDEX(_xlfn.TEXTSPLIT(U62,",",),0,1)+$AC$1,$AC$1))/2,0),ROUNDUP(IF(MOD(AK$1+INDEX(_xlfn.TEXTSPLIT(U62,",",),0,2)+$AC$1,$AC$1)=0,$AC$1,MOD(AK$1+INDEX(_xlfn.TEXTSPLIT(U62,",",),0,2)+$AC$1,$AC$1))/2,0))} -> -3
C4: 3 | D4: =IF(RAND()<=$B$1,4,8) -> 4 | E4: =IF(RAND()<=$B$1,4,8) -> 8 | F4: =IF(RAND()<=$B$1,4,8) -> 8 | G4: =IF(RAND()<=$B$1,4,8) -> 8 | H4: =IF(RAND()<=$B$1,4,8) -> 8 | J4: 3 | K4: {=INDEX($D$2:$H$6,ROUNDUP(IF(MOD($J4+INDEX(_xlfn.TEXTSPLIT(B63,",",),0,1)+$J$1,$J$1)=0,$J$1,MOD($J4+INDEX(_xlfn.TEXTSPLIT(B63,",",),0,1)+$J$1,$J$1))/2,0),ROUNDUP(IF(MOD(K$1+INDEX(_xlfn.TEXTSPLIT(B63,",",),0,2)+$J$1,$J$1)=0,$J$1,MOD(K$1+INDEX(_xlfn.TEXTSPLIT(B63,",",),0,2)+$J$1,$J$1))/2,0))} -> 8 | L4: {=INDEX($D$2:$H$6,ROUNDUP(IF(MOD($J4+INDEX(_xlfn.TEXTSPLIT(C63,",",),0,1)+$J$1,$J$1)=0,$J$1,MOD($J4+INDEX(_xlfn.TEXTSPLIT(C63,",",),0,1)+$J$1,$J$1))/2,0),ROUNDUP(IF(MOD(L$1+INDEX(_xlfn.TEXTSPLIT(C63,",",),0,2)+$J$1,$J$1)=0,$J$1,MOD(L$1+INDEX(_xlfn.TEXTSPLIT(C63,",",),0,2)+$J$1,$J$1))/2,0))} -> 8 | M4: {=INDEX($D$2:$H$6,ROUNDUP(IF(MOD($J4+INDEX(_xlfn.TEXTSPLIT(D63,",",),0,1)+$J$1,$J$1)=0,$J$1,MOD($J4+INDEX(_xlfn.TEXTSPLIT(D63,",",),0,1)+$J$1,$J$1))/2,0),ROUNDUP(IF(MOD(M$1+INDEX(_xlfn.TEXTSPLIT(D63,",",),0,2)+$J$1,$J$1)=0,$J$1,MOD(M$1+INDEX(_xlfn.TEXTSPLIT(D63,",",),0,2)+$J$1,$J$1))/2,0))} -> 8 | N4: {=INDEX($D$2:$H$6,ROUNDUP(IF(MOD($J4+INDEX(_xlfn.TEXTSPLIT(E63,",",),0,1)+$J$1,$J$1)=0,$J$1,MOD($J4+INDEX(_xlfn.TEXTSPLIT(E63,",",),0,1)+$J$1,$J$1))/2,0),ROUNDUP(IF(MOD(N$1+INDEX(_xlfn.TEXTSPLIT(E63,",",),0,2)+$J$1,$J$1)=0,$J$1,MOD(N$1+INDEX(_xlfn.TEXTSPLIT(E63,",",),0,2)+$J$1,$J$1))/2,0))} -> 4 | O4: {=INDEX($D$2:$H$6,ROUNDUP(IF(MOD($J4+INDEX(_xlfn.TEXTSPLIT(F63,",",),0,1)+$J$1,$J$1)=0,$J$1,MOD($J4+INDEX(_xlfn.TEXTSPLIT(F63,",",),0,1)+$J$1,$J$1))/2,0),ROUNDUP(IF(MOD(O$1+INDEX(_xlfn.TEXTSPLIT(F63,",",),0,2)+$J$1,$J$1)=0,$J$1,MOD(O$1+INDEX(_xlfn.TEXTSPLIT(F63,",",),0,2)+$J$1,$J$1))/2,0))} -> 8 | P4: {=INDEX($D$2:$H$6,ROUNDUP(IF(MOD($J4+INDEX(_xlfn.TEXTSPLIT(G63,",",),0,1)+$J$1,$J$1)=0,$J$1,MOD($J4+INDEX(_xlfn.TEXTSPLIT(G63,",",),0,1)+$J$1,$J$1))/2,0),ROUNDUP(IF(MOD(P$1+INDEX(_xlfn.TEXTSPLIT(G63,",",),0,2)+$J$1,$J$1)=0,$J$1,MOD(P$1+INDEX(_xlfn.TEXTSPLIT(G63,",",),0,2)+$J$1,$J$1))/2,0))} -> 8 | Q4: {=INDEX($D$2:$H$6,ROUNDUP(IF(MOD($J4+INDEX(_xlfn.TEXTSPLIT(H63,",",),0,1)+$J$1,$J$1)=0,$J$1,MOD($J4+INDEX(_xlfn.TEXTSPLIT(H63,",",),0,1)+$J$1,$J$1))/2,0),ROUNDUP(IF(MOD(Q$1+INDEX(_xlfn.TEXTSPLIT(H63,",",),0,2)+$J$1,$J$1)=0,$J$1,MOD(Q$1+INDEX(_xlfn.TEXTSPLIT(H63,",",),0,2)+$J$1,$J$1))/2,0))} -> 4 | R4: {=INDEX($D$2:$H$6,ROUNDUP(IF(MOD($J4+INDEX(_xlfn.TEXTSPLIT(I63,",",),0,1)+$J$1,$J$1)=0,$J$1,MOD($J4+INDEX(_xlfn.TEXTSPLIT(I63,",",),0,1)+$J$1,$J$1))/2,0),ROUNDUP(IF(MOD(R$1+INDEX(_xlfn.TEXTSPLIT(I63,",",),0,2)+$J$1,$J$1)=0,$J$1,MOD(R$1+INDEX(_xlfn.TEXTSPLIT(I63,",",),0,2)+$J$1,$J$1))/2,0))} -> 8 | ... T4: {=INDEX($D$2:$H$6,ROUNDUP(IF(MOD($J4+INDEX(_xlfn.TEXTSPLIT(K63,",",),0,1)+$J$1,$J$1)=0,$J$1,MOD($J4+INDEX(_xlfn.TEXTSPLIT(K63,",",),0,1)+$J$1,$J$1))/2,0),ROUNDUP(IF(MOD(T$1+INDEX(_xlfn.TEXTSPLIT(K63,",",),0,2)+$J$1,$J$1)=0,$J$1,MOD(T$1+INDEX(_xlfn.TEXTSPLIT(K63,",",),0,2)+$J$1,$J$1))/2,0))} -> 8 | W4: 3 | X4: =RANDBETWEEN(-3,0) -> -2 | Y4: =RANDBETWEEN(-3,0) -> -1 | Z4: =RANDBETWEEN(-3,0) -> -1 | AA4: =RANDBETWEEN(-3,0) -> 0 | AC4: 3 | AD4: {=INDEX($X$2:$AA$5,ROUNDUP(IF(MOD($AC4+INDEX(_xlfn.TEXTSPLIT(N63,",",),0,1)+$AC$1,$AC$1)=0,$AC$1,MOD($AC4+INDEX(_xlfn.TEXTSPLIT(N63,",",),0,1)+$AC$1,$AC$1))/2,0),ROUNDUP(IF(MOD(AD$1+INDEX(_xlfn.TEXTSPLIT(N63,",",),0,2)+$AC$1,$AC$1)=0,$AC$1,MOD(AD$1+INDEX(_xlfn.TEXTSPLIT(N63,",",),0,2)+$AC$1,$AC$1))/2,0))} -> -2 | AE4: {=INDEX($X$2:$AA$5,ROUNDUP(IF(MOD($AC4+INDEX(_xlfn.TEXTSPLIT(O63,",",),0,1)+$AC$1,$AC$1)=0,$AC$1,MOD($AC4+INDEX(_xlfn.TEXTSPLIT(O63,",",),0,1)+$AC$1,$AC$1))/2,0),ROUNDUP(IF(MOD(AE$1+INDEX(_xlfn.TEXTSPLIT(O63,",",),0,2)+$AC$1,$AC$1)=0,$AC$1,MOD(AE$1+INDEX(_xlfn.TEXTSPLIT(O63,",",),0,2)+$AC$1,$AC$1))/2,0))} -> -1 | AF4: {=INDEX($X$2:$AA$5,ROUNDUP(IF(MOD($AC4+INDEX(_xlfn.TEXTSPLIT(P63,",",),0,1)+$AC$1,$AC$1)=0,$AC$1,MOD($AC4+INDEX(_xlfn.TEXTSPLIT(P63,",",),0,1)+$AC$1,$AC$1))/2,0),ROUNDUP(IF(MOD(AF$1+INDEX(_xlfn.TEXTSPLIT(P63,",",),0,2)+$AC$1,$AC$1)=0,$AC$1,MOD(AF$1+INDEX(_xlfn.TEXTSPLIT(P63,",",),0,2)+$AC$1,$AC$1))/2,0))} -> -1 | AG4: {=INDEX($X$2:$AA$5,ROUNDUP(IF(MOD($AC4+INDEX(_xlfn.TEXTSPLIT(Q63,",",),0,1)+$AC$1,$AC$1)=0,$AC$1,MOD($AC4+INDEX(_xlfn.TEXTSPLIT(Q63,",",),0,1)+$AC$1,$AC$1))/2,0),ROUNDUP(IF(MOD(AG$1+INDEX(_xlfn.TEXTSPLIT(Q63,",",),0,2)+$AC$1,$AC$1)=0,$AC$1,MOD(AG$1+INDEX(_xlfn.TEXTSPLIT(Q63,",",),0,2)+$AC$1,$AC$1))/2,0))} -> -3 | AH4: {=INDEX($X$2:$AA$5,ROUNDUP(IF(MOD($AC4+INDEX(_xlfn.TEXTSPLIT(R63,",",),0,1)+$AC$1,$AC$1)=0,$AC$1,MOD($AC4+INDEX(_xlfn.TEXTSPLIT(R63,",",),0,1)+$AC$1,$AC$1))/2,0),ROUNDUP(IF(MOD(AH$1+INDEX(_xlfn.TEXTSPLIT(R63,",",),0,2)+$AC$1,$AC$1)=0,$AC$1,MOD(AH$1+INDEX(_xlfn.TEXTSPLIT(R63,",",),0,2)+$AC$1,$AC$1))/2,0))} -> -1 | AI4: {=INDEX($X$2:$AA$5,ROUNDUP(IF(MOD($AC4+INDEX(_xlfn.TEXTSPLIT(S63,",",),0,1)+$AC$1,$AC$1)=0,$AC$1,MOD($AC4+INDEX(_xlfn.TEXTSPLIT(S63,",",),0,1)+$AC$1,$AC$1))/2,0),ROUNDUP(IF(MOD(AI$1+INDEX(_xlfn.TEXTSPLIT(S63,",",),0,2)+$AC$1,$AC$1)=0,$AC$1,MOD(AI$1+INDEX(_xlfn.TEXTSPLIT(S63,",",),0,2)+$AC$1,$AC$1))/2,0))} -> -3 | AJ4: {=INDEX($X$2:$AA$5,ROUNDUP(IF(MOD($AC4+INDEX(_xlfn.TEXTSPLIT(T63,",",),0,1)+$AC$1,$AC$1)=0,$AC$1,MOD($AC4+INDEX(_xlfn.TEXTSPLIT(T63,",",),0,1)+$AC$1,$AC$1))/2,0),ROUNDUP(IF(MOD(AJ$1+INDEX(_xlfn.TEXTSPLIT(T63,",",),0,2)+$AC$1,$AC$1)=0,$AC$1,MOD(AJ$1+INDEX(_xlfn.TEXTSPLIT(T63,",",),0,2)+$AC$1,$AC$1))/2,0))} -> -3 | AK4: {=INDEX($X$2:$AA$5,ROUNDUP(IF(MOD($AC4+INDEX(_xlfn.TEXTSPLIT(U63,",",),0,1)+$AC$1,$AC$1)=0,$AC$1,MOD($AC4+INDEX(_xlfn.TEXTSPLIT(U63,",",),0,1)+$AC$1,$AC$1))/2,0),ROUNDUP(IF(MOD(AK$1+INDEX(_xlfn.TEXTSPLIT(U63,",",),0,2)+$AC$1,$AC$1)=0,$AC$1,MOD(AK$1+INDEX(_xlfn.TEXTSPLIT(U63,",",),0,2)+$AC$1,$AC$1))/2,0))} -> -3
C5: 4 | D5: =IF(RAND()<=$B$1,4,8) -> 4 | E5: =IF(RAND()<=$B$1,4,8) -> 8 | F5: =IF(RAND()<=$B$1,4,8) -> 8 | G5: =IF(RAND()<=$B$1,4,8) -> 8 | H5: =IF(RAND()<=$B$1,4,8) -> 8 | J5: 4 | K5: {=INDEX($D$2:$H$6,ROUNDUP(IF(MOD($J5+INDEX(_xlfn.TEXTSPLIT(B64,",",),0,1)+$J$1,$J$1)=0,$J$1,MOD($J5+INDEX(_xlfn.TEXTSPLIT(B64,",",),0,1)+$J$1,$J$1))/2,0),ROUNDUP(IF(MOD(K$1+INDEX(_xlfn.TEXTSPLIT(B64,",",),0,2)+$J$1,$J$1)=0,$J$1,MOD(K$1+INDEX(_xlfn.TEXTSPLIT(B64,",",),0,2)+$J$1,$J$1))/2,0))} -> 8 | L5: {=INDEX($D$2:$H$6,ROUNDUP(IF(MOD($J5+INDEX(_xlfn.TEXTSPLIT(C64,",",),0,1)+$J$1,$J$1)=0,$J$1,MOD($J5+INDEX(_xlfn.TEXTSPLIT(C64,",",),0,1)+$J$1,$J$1))/2,0),ROUNDUP(IF(MOD(L$1+INDEX(_xlfn.TEXTSPLIT(C64,",",),0,2)+$J$1,$J$1)=0,$J$1,MOD(L$1+INDEX(_xlfn.TEXTSPLIT(C64,",",),0,2)+$J$1,$J$1))/2,0))} -> 8 | M5: {=INDEX($D$2:$H$6,ROUNDUP(IF(MOD($J5+INDEX(_xlfn.TEXTSPLIT(D64,",",),0,1)+$J$1,$J$1)=0,$J$1,MOD($J5+INDEX(_xlfn.TEXTSPLIT(D64,",",),0,1)+$J$1,$J$1))/2,0),ROUNDUP(IF(MOD(M$1+INDEX(_xlfn.TEXTSPLIT(D64,",",),0,2)+$J$1,$J$1)=0,$J$1,MOD(M$1+INDEX(_xlfn.TEXTSPLIT(D64,",",),0,2)+$J$1,$J$1))/2,0))} -> 8 | N5: {=INDEX($D$2:$H$6,ROUNDUP(IF(MOD($J5+INDEX(_xlfn.TEXTSPLIT(E64,",",),0,1)+$J$1,$J$1)=0,$J$1,MOD($J5+INDEX(_xlfn.TEXTSPLIT(E64,",",),0,1)+$J$1,$J$1))/2,0),ROUNDUP(IF(MOD(N$1+INDEX(_xlfn.TEXTSPLIT(E64,",",),0,2)+$J$1,$J$1)=0,$J$1,MOD(N$1+INDEX(_xlfn.TEXTSPLIT(E64,",",),0,2)+$J$1,$J$1))/2,0))} -> 8 | O5: {=INDEX($D$2:$H$6,ROUNDUP(IF(MOD($J5+INDEX(_xlfn.TEXTSPLIT(F64,",",),0,1)+$J$1,$J$1)=0,$J$1,MOD($J5+INDEX(_xlfn.TEXTSPLIT(F64,",",),0,1)+$J$1,$J$1))/2,0),ROUNDUP(IF(MOD(O$1+INDEX(_xlfn.TEXTSPLIT(F64,",",),0,2)+$J$1,$J$1)=0,$J$1,MOD(O$1+INDEX(_xlfn.TEXTSPLIT(F64,",",),0,2)+$J$1,$J$1))/2,0))} -> 8 | P5: {=INDEX($D$2:$H$6,ROUNDUP(IF(MOD($J5+INDEX(_xlfn.TEXTSPLIT(G64,",",),0,1)+$J$1,$J$1)=0,$J$1,MOD($J5+INDEX(_xlfn.TEXTSPLIT(G64,",",),0,1)+$J$1,$J$1))/2,0),ROUNDUP(IF(MOD(P$1+INDEX(_xlfn.TEXTSPLIT(G64,",",),0,2)+$J$1,$J$1)=0,$J$1,MOD(P$1+INDEX(_xlfn.TEXTSPLIT(G64,",",),0,2)+$J$1,$J$1))/2,0))} -> 4 | Q5: {=INDEX($D$2:$H$6,ROUNDUP(IF(MOD($J5+INDEX(_xlfn.TEXTSPLIT(H64,",",),0,1)+$J$1,$J$1)=0,$J$1,MOD($J5+INDEX(_xlfn.TEXTSPLIT(H64,",",),0,1)+$J$1,$J$1))/2,0),ROUNDUP(IF(MOD(Q$1+INDEX(_xlfn.TEXTSPLIT(H64,",",),0,2)+$J$1,$J$1)=0,$J$1,MOD(Q$1+INDEX(_xlfn.TEXTSPLIT(H64,",",),0,2)+$J$1,$J$1))/2,0))} -> 8 | R5: {=INDEX($D$2:$H$6,ROUNDUP(IF(MOD($J5+INDEX(_xlfn.TEXTSPLIT(I64,",",),0,1)+$J$1,$J$1)=0,$J$1,MOD($J5+INDEX(_xlfn.TEXTSPLIT(I64,",",),0,1)+$J$1,$J$1))/2,0),ROUNDUP(IF(MOD(R$1+INDEX(_xlfn.TEXTSPLIT(I64,",",),0,2)+$J$1,$J$1)=0,$J$1,MOD(R$1+INDEX(_xlfn.TEXTSPLIT(I64,",",),0,2)+$J$1,$J$1))/2,0))} -> 8 | ... T5: {=INDEX($D$2:$H$6,ROUNDUP(IF(MOD($J5+INDEX(_xlfn.TEXTSPLIT(K64,",",),0,1)+$J$1,$J$1)=0,$J$1,MOD($J5+INDEX(_xlfn.TEXTSPLIT(K64,",",),0,1)+$J$1,$J$1))/2,0),ROUNDUP(IF(MOD(T$1+INDEX(_xlfn.TEXTSPLIT(K64,",",),0,2)+$J$1,$J$1)=0,$J$1,MOD(T$1+INDEX(_xlfn.TEXTSPLIT(K64,",",),0,2)+$J$1,$J$1))/2,0))} -> 8 | W5: 4 | X5: =RANDBETWEEN(-3,0) -> -1 | Y5: =RANDBETWEEN(-3,0) -> -1 | Z5: =RANDBETWEEN(-3,0) -> 0 | AA5: =RANDBETWEEN(-3,0) -> -3 | AC5: 4 | AD5: {=INDEX($X$2:$AA$5,ROUNDUP(IF(MOD($AC5+INDEX(_xlfn.TEXTSPLIT(N64,",",),0,1)+$AC$1,$AC$1)=0,$AC$1,MOD($AC5+INDEX(_xlfn.TEXTSPLIT(N64,",",),0,1)+$AC$1,$AC$1))/2,0),ROUNDUP(IF(MOD(AD$1+INDEX(_xlfn.TEXTSPLIT(N64,",",),0,2)+$AC$1,$AC$1)=0,$AC$1,MOD(AD$1+INDEX(_xlfn.TEXTSPLIT(N64,",",),0,2)+$AC$1,$AC$1))/2,0))} -> -2 | AE5: {=INDEX($X$2:$AA$5,ROUNDUP(IF(MOD($AC5+INDEX(_xlfn.TEXTSPLIT(O64,",",),0,1)+$AC$1,$AC$1)=0,$AC$1,MOD($AC5+INDEX(_xlfn.TEXTSPLIT(O64,",",),0,1)+$AC$1,$AC$1))/2,0),ROUNDUP(IF(MOD(AE$1+INDEX(_xlfn.TEXTSPLIT(O64,",",),0,2)+$AC$1,$AC$1)=0,$AC$1,MOD(AE$1+INDEX(_xlfn.TEXTSPLIT(O64,",",),0,2)+$AC$1,$AC$1))/2,0))} -> -2 | AF5: {=INDEX($X$2:$AA$5,ROUNDUP(IF(MOD($AC5+INDEX(_xlfn.TEXTSPLIT(P64,",",),0,1)+$AC$1,$AC$1)=0,$AC$1,MOD($AC5+INDEX(_xlfn.TEXTSPLIT(P64,",",),0,1)+$AC$1,$AC$1))/2,0),ROUNDUP(IF(MOD(AF$1+INDEX(_xlfn.TEXTSPLIT(P64,",",),0,2)+$AC$1,$AC$1)=0,$AC$1,MOD(AF$1+INDEX(_xlfn.TEXTSPLIT(P64,",",),0,2)+$AC$1,$AC$1))/2,0))} -> -1 | AG5: {=INDEX($X$2:$AA$5,ROUNDUP(IF(MOD($AC5+INDEX(_xlfn.TEXTSPLIT(Q64,",",),0,1)+$AC$1,$AC$1)=0,$AC$1,MOD($AC5+INDEX(_xlfn.TEXTSPLIT(Q64,",",),0,1)+$AC$1,$AC$1))/2,0),ROUNDUP(IF(MOD(AG$1+INDEX(_xlfn.TEXTSPLIT(Q64,",",),0,2)+$AC$1,$AC$1)=0,$AC$1,MOD(AG$1+INDEX(_xlfn.TEXTSPLIT(Q64,",",),0,2)+$AC$1,$AC$1))/2,0))} -> -1 | AH5: {=INDEX($X$2:$AA$5,ROUNDUP(IF(MOD($AC5+INDEX(_xlfn.TEXTSPLIT(R64,",",),0,1)+$AC$1,$AC$1)=0,$AC$1,MOD($AC5+INDEX(_xlfn.TEXTSPLIT(R64,",",),0,1)+$AC$1,$AC$1))/2,0),ROUNDUP(IF(MOD(AH$1+INDEX(_xlfn.TEXTSPLIT(R64,",",),0,2)+$AC$1,$AC$1)=0,$AC$1,MOD(AH$1+INDEX(_xlfn.TEXTSPLIT(R64,",",),0,2)+$AC$1,$AC$1))/2,0))} -> -1 | AI5: {=INDEX($X$2:$AA$5,ROUNDUP(IF(MOD($AC5+INDEX(_xlfn.TEXTSPLIT(S64,",",),0,1)+$AC$1,$AC$1)=0,$AC$1,MOD($AC5+INDEX(_xlfn.TEXTSPLIT(S64,",",),0,1)+$AC$1,$AC$1))/2,0),ROUNDUP(IF(MOD(AI$1+INDEX(_xlfn.TEXTSPLIT(S64,",",),0,2)+$AC$1,$AC$1)=0,$AC$1,MOD(AI$1+INDEX(_xlfn.TEXTSPLIT(S64,",",),0,2)+$AC$1,$AC$1))/2,0))} -> 0 | AJ5: {=INDEX($X$2:$AA$5,ROUNDUP(IF(MOD($AC5+INDEX(_xlfn.TEXTSPLIT(T64,",",),0,1)+$AC$1,$AC$1)=0,$AC$1,MOD($AC5+INDEX(_xlfn.TEXTSPLIT(T64,",",),0,1)+$AC$1,$AC$1))/2,0),ROUNDUP(IF(MOD(AJ$1+INDEX(_xlfn.TEXTSPLIT(T64,",",),0,2)+$AC$1,$AC$1)=0,$AC$1,MOD(AJ$1+INDEX(_xlfn.TEXTSPLIT(T64,",",),0,2)+$AC$1,$AC$1))/2,0))} -> -1 | AK5: {=INDEX($X$2:$AA$5,ROUNDUP(IF(MOD($AC5+INDEX(_xlfn.TEXTSPLIT(U64,",",),0,1)+$AC$1,$AC$1)=0,$AC$1,MOD($AC5+INDEX(_xlfn.TEXTSPLIT(U64,",",),0,1)+$AC$1,$AC$1))/2,0),ROUNDUP(IF(MOD(AK$1+INDEX(_xlfn.TEXTSPLIT(U64,",",),0,2)+$AC$1,$AC$1)=0,$AC$1,MOD(AK$1+INDEX(_xlfn.TEXTSPLIT(U64,",",),0,2)+$AC$1,$AC$1))/2,0))} -> -3
C6: 5 | D6: =IF(RAND()<=$B$1,4,8) -> 8 | E6: =IF(RAND()<=$B$1,4,8) -> 4 | F6: =IF(RAND()<=$B$1,4,8) -> 8 | G6: =IF(RAND()<=$B$1,4,8) -> 8 | H6: =IF(RAND()<=$B$1,4,8) -> 8 | J6: 5 | K6: {=INDEX($D$2:$H$6,ROUNDUP(IF(MOD($J6+INDEX(_xlfn.TEXTSPLIT(B65,",",),0,1)+$J$1,$J$1)=0,$J$1,MOD($J6+INDEX(_xlfn.TEXTSPLIT(B65,",",),0,1)+$J$1,$J$1))/2,0),ROUNDUP(IF(MOD(K$1+INDEX(_xlfn.TEXTSPLIT(B65,",",),0,2)+$J$1,$J$1)=0,$J$1,MOD(K$1+INDEX(_xlfn.TEXTSPLIT(B65,",",),0,2)+$J$1,$J$1))/2,0))} -> 4 | L6: {=INDEX($D$2:$H$6,ROUNDUP(IF(MOD($J6+INDEX(_xlfn.TEXTSPLIT(C65,",",),0,1)+$J$1,$J$1)=0,$J$1,MOD($J6+INDEX(_xlfn.TEXTSPLIT(C65,",",),0,1)+$J$1,$J$1))/2,0),ROUNDUP(IF(MOD(L$1+INDEX(_xlfn.TEXTSPLIT(C65,",",),0,2)+$J$1,$J$1)=0,$J$1,MOD(L$1+INDEX(_xlfn.TEXTSPLIT(C65,",",),0,2)+$J$1,$J$1))/2,0))} -> 4 | M6: {=INDEX($D$2:$H$6,ROUNDUP(IF(MOD($J6+INDEX(_xlfn.TEXTSPLIT(D65,",",),0,1)+$J$1,$J$1)=0,$J$1,MOD($J6+INDEX(_xlfn.TEXTSPLIT(D65,",",),0,1)+$J$1,$J$1))/2,0),ROUNDUP(IF(MOD(M$1+INDEX(_xlfn.TEXTSPLIT(D65,",",),0,2)+$J$1,$J$1)=0,$J$1,MOD(M$1+INDEX(_xlfn.TEXTSPLIT(D65,",",),0,2)+$J$1,$J$1))/2,0))} -> 8 | N6: {=INDEX($D$2:$H$6,ROUNDUP(IF(MOD($J6+INDEX(_xlfn.TEXTSPLIT(E65,",",),0,1)+$J$1,$J$1)=0,$J$1,MOD($J6+INDEX(_xlfn.TEXTSPLIT(E65,",",),0,1)+$J$1,$J$1))/2,0),ROUNDUP(IF(MOD(N$1+INDEX(_xlfn.TEXTSPLIT(E65,",",),0,2)+$J$1,$J$1)=0,$J$1,MOD(N$1+INDEX(_xlfn.TEXTSPLIT(E65,",",),0,2)+$J$1,$J$1))/2,0))} -> 8 | O6: {=INDEX($D$2:$H$6,ROUNDUP(IF(MOD($J6+INDEX(_xlfn.TEXTSPLIT(F65,",",),0,1)+$J$1,$J$1)=0,$J$1,MOD($J6+INDEX(_xlfn.TEXTSPLIT(F65,",",),0,1)+$J$1,$J$1))/2,0),ROUNDUP(IF(MOD(O$1+INDEX(_xlfn.TEXTSPLIT(F65,",",),0,2)+$J$1,$J$1)=0,$J$1,MOD(O$1+INDEX(_xlfn.TEXTSPLIT(F65,",",),0,2)+$J$1,$J$1))/2,0))} -> 4 | P6: {=INDEX($D$2:$H$6,ROUNDUP(IF(MOD($J6+INDEX(_xlfn.TEXTSPLIT(G65,",",),0,1)+$J$1,$J$1)=0,$J$1,MOD($J6+INDEX(_xlfn.TEXTSPLIT(G65,",",),0,1)+$J$1,$J$1))/2,0),ROUNDUP(IF(MOD(P$1+INDEX(_xlfn.TEXTSPLIT(G65,",",),0,2)+$J$1,$J$1)=0,$J$1,MOD(P$1+INDEX(_xlfn.TEXTSPLIT(G65,",",),0,2)+$J$1,$J$1))/2,0))} -> 8 | Q6: {=INDEX($D$2:$H$6,ROUNDUP(IF(MOD($J6+INDEX(_xlfn.TEXTSPLIT(H65,",",),0,1)+$J$1,$J$1)=0,$J$1,MOD($J6+INDEX(_xlfn.TEXTSPLIT(H65,",",),0,1)+$J$1,$J$1))/2,0),ROUNDUP(IF(MOD(Q$1+INDEX(_xlfn.TEXTSPLIT(H65,",",),0,2)+$J$1,$J$1)=0,$J$1,MOD(Q$1+INDEX(_xlfn.TEXTSPLIT(H65,",",),0,2)+$J$1,$J$1))/2,0))} -> 8 | R6: {=INDEX($D$2:$H$6,ROUNDUP(IF(MOD($J6+INDEX(_xlfn.TEXTSPLIT(I65,",",),0,1)+$J$1,$J$1)=0,$J$1,MOD($J6+INDEX(_xlfn.TEXTSPLIT(I65,",",),0,1)+$J$1,$J$1))/2,0),ROUNDUP(IF(MOD(R$1+INDEX(_xlfn.TEXTSPLIT(I65,",",),0,2)+$J$1,$J$1)=0,$J$1,MOD(R$1+INDEX(_xlfn.TEXTSPLIT(I65,",",),0,2)+$J$1,$J$1))/2,0))} -> 8 | ... T6: {=INDEX($D$2:$H$6,ROUNDUP(IF(MOD($J6+INDEX(_xlfn.TEXTSPLIT(K65,",",),0,1)+$J$1,$J$1)=0,$J$1,MOD($J6+INDEX(_xlfn.TEXTSPLIT(K65,",",),0,1)+$J$1,$J$1))/2,0),ROUNDUP(IF(MOD(T$1+INDEX(_xlfn.TEXTSPLIT(K65,",",),0,2)+$J$1,$J$1)=0,$J$1,MOD(T$1+INDEX(_xlfn.TEXTSPLIT(K65,",",),0,2)+$J$1,$J$1))/2,0))} -> 8 | AC6: 5 | AD6: {=INDEX($X$2:$AA$5,ROUNDUP(IF(MOD($AC6+INDEX(_xlfn.TEXTSPLIT(N65,",",),0,1)+$AC$1,$AC$1)=0,$AC$1,MOD($AC6+INDEX(_xlfn.TEXTSPLIT(N65,",",),0,1)+$AC$1,$AC$1))/2,0),ROUNDUP(IF(MOD(AD$1+INDEX(_xlfn.TEXTSPLIT(N65,",",),0,2)+$AC$1,$AC$1)=0,$AC$1,MOD(AD$1+INDEX(_xlfn.TEXTSPLIT(N65,",",),0,2)+$AC$1,$AC$1))/2,0))} -> -3 | AE6: {=INDEX($X$2:$AA$5,ROUNDUP(IF(MOD($AC6+INDEX(_xlfn.TEXTSPLIT(O65,",",),0,1)+$AC$1,$AC$1)=0,$AC$1,MOD($AC6+INDEX(_xlfn.TEXTSPLIT(O65,",",),0,1)+$AC$1,$AC$1))/2,0),ROUNDUP(IF(MOD(AE$1+INDEX(_xlfn.TEXTSPLIT(O65,",",),0,2)+$AC$1,$AC$1)=0,$AC$1,MOD(AE$1+INDEX(_xlfn.TEXTSPLIT(O65,",",),0,2)+$AC$1,$AC$1))/2,0))} -> -1 | AF6: {=INDEX($X$2:$AA$5,ROUNDUP(IF(MOD($AC6+INDEX(_xlfn.TEXTSPLIT(P65,",",),0,1)+$AC$1,$AC$1)=0,$AC$1,MOD($AC6+INDEX(_xlfn.TEXTSPLIT(P65,",",),0,1)+$AC$1,$AC$1))/2,0),ROUNDUP(IF(MOD(AF$1+INDEX(_xlfn.TEXTSPLIT(P65,",",),0,2)+$AC$1,$AC$1)=0,$AC$1,MOD(AF$1+INDEX(_xlfn.TEXTSPLIT(P65,",",),0,2)+$AC$1,$AC$1))/2,0))} -> -1 | AG6: {=INDEX($X$2:$AA$5,ROUNDUP(IF(MOD($AC6+INDEX(_xlfn.TEXTSPLIT(Q65,",",),0,1)+$AC$1,$AC$1)=0,$AC$1,MOD($AC6+INDEX(_xlfn.TEXTSPLIT(Q65,",",),0,1)+$AC$1,$AC$1))/2,0),ROUNDUP(IF(MOD(AG$1+INDEX(_xlfn.TEXTSPLIT(Q65,",",),0,2)+$AC$1,$AC$1)=0,$AC$1,MOD(AG$1+INDEX(_xlfn.TEXTSPLIT(Q65,",",),0,2)+$AC$1,$AC$1))/2,0))} -> -1 | AH6: {=INDEX($X$2:$AA$5,ROUNDUP(IF(MOD($AC6+INDEX(_xlfn.TEXTSPLIT(R65,",",),0,1)+$AC$1,$AC$1)=0,$AC$1,MOD($AC6+INDEX(_xlfn.TEXTSPLIT(R65,",",),0,1)+$AC$1,$AC$1))/2,0),ROUNDUP(IF(MOD(AH$1+INDEX(_xlfn.TEXTSPLIT(R65,",",),0,2)+$AC$1,$AC$1)=0,$AC$1,MOD(AH$1+INDEX(_xlfn.TEXTSPLIT(R65,",",),0,2)+$AC$1,$AC$1))/2,0))} -> -1 | AI6: {=INDEX($X$2:$AA$5,ROUNDUP(IF(MOD($AC6+INDEX(_xlfn.TEXTSPLIT(S65,",",),0,1)+$AC$1,$AC$1)=0,$AC$1,MOD($AC6+INDEX(_xlfn.TEXTSPLIT(S65,",",),0,1)+$AC$1,$AC$1))/2,0),ROUNDUP(IF(MOD(AI$1+INDEX(_xlfn.TEXTSPLIT(S65,",",),0,2)+$AC$1,$AC$1)=0,$AC$1,MOD(AI$1+INDEX(_xlfn.TEXTSPLIT(S65,",",),0,2)+$AC$1,$AC$1))/2,0))} -> 0 | AJ6: {=INDEX($X$2:$AA$5,ROUNDUP(IF(MOD($AC6+INDEX(_xlfn.TEXTSPLIT(T65,",",),0,1)+$AC$1,$AC$1)=0,$AC$1,MOD($AC6+INDEX(_xlfn.TEXTSPLIT(T65,",",),0,1)+$AC$1,$AC$1))/2,0),ROUNDUP(IF(MOD(AJ$1+INDEX(_xlfn.TEXTSPLIT(T65,",",),0,2)+$AC$1,$AC$1)=0,$AC$1,MOD(AJ$1+INDEX(_xlfn.TEXTSPLIT(T65,",",),0,2)+$AC$1,$AC$1))/2,0))} -> -1 | AK6: {=INDEX($X$2:$AA$5,ROUNDUP(IF(MOD($AC6+INDEX(_xlfn.TEXTSPLIT(U65,",",),0,1)+$AC$1,$AC$1)=0,$AC$1,MOD($AC6+INDEX(_xlfn.TEXTSPLIT(U65,",",),0,1)+$AC$1,$AC$1))/2,0),ROUNDUP(IF(MOD(AK$1+INDEX(_xlfn.TEXTSPLIT(U65,",",),0,2)+$AC$1,$AC$1)=0,$AC$1,MOD(AK$1+INDEX(_xlfn.TEXTSPLIT(U65,",",),0,2)+$AC$1,$AC$1))/2,0))} -> 0
A7: =ROUND(25*E8,0) -> 5 | D7: How Many | E7: Percent | J7: 6 | K7: {=INDEX($D$2:$H$6,ROUNDUP(IF(MOD($J7+INDEX(_xlfn.TEXTSPLIT(B66,",",),0,1)+$J$1,$J$1)=0,$J$1,MOD($J7+INDEX(_xlfn.TEXTSPLIT(B66,",",),0,1)+$J$1,$J$1))/2,0),ROUNDUP(IF(MOD(K$1+INDEX(_xlfn.TEXTSPLIT(B66,",",),0,2)+$J$1,$J$1)=0,$J$1,MOD(K$1+INDEX(_xlfn.TEXTSPLIT(B66,",",),0,2)+$J$1,$J$1))/2,0))} -> 4 | L7: {=INDEX($D$2:$H$6,ROUNDUP(IF(MOD($J7+INDEX(_xlfn.TEXTSPLIT(C66,",",),0,1)+$J$1,$J$1)=0,$J$1,MOD($J7+INDEX(_xlfn.TEXTSPLIT(C66,",",),0,1)+$J$1,$J$1))/2,0),ROUNDUP(IF(MOD(L$1+INDEX(_xlfn.TEXTSPLIT(C66,",",),0,2)+$J$1,$J$1)=0,$J$1,MOD(L$1+INDEX(_xlfn.TEXTSPLIT(C66,",",),0,2)+$J$1,$J$1))/2,0))} -> 4 | M7: {=INDEX($D$2:$H$6,ROUNDUP(IF(MOD($J7+INDEX(_xlfn.TEXTSPLIT(D66,",",),0,1)+$J$1,$J$1)=0,$J$1,MOD($J7+INDEX(_xlfn.TEXTSPLIT(D66,",",),0,1)+$J$1,$J$1))/2,0),ROUNDUP(IF(MOD(M$1+INDEX(_xlfn.TEXTSPLIT(D66,",",),0,2)+$J$1,$J$1)=0,$J$1,MOD(M$1+INDEX(_xlfn.TEXTSPLIT(D66,",",),0,2)+$J$1,$J$1))/2,0))} -> 8 | N7: {=INDEX($D$2:$H$6,ROUNDUP(IF(MOD($J7+INDEX(_xlfn.TEXTSPLIT(E66,",",),0,1)+$J$1,$J$1)=0,$J$1,MOD($J7+INDEX(_xlfn.TEXTSPLIT(E66,",",),0,1)+$J$1,$J$1))/2,0),ROUNDUP(IF(MOD(N$1+INDEX(_xlfn.TEXTSPLIT(E66,",",),0,2)+$J$1,$J$1)=0,$J$1,MOD(N$1+INDEX(_xlfn.TEXTSPLIT(E66,",",),0,2)+$J$1,$J$1))/2,0))} -> 8 | O7: {=INDEX($D$2:$H$6,ROUNDUP(IF(MOD($J7+INDEX(_xlfn.TEXTSPLIT(F66,",",),0,1)+$J$1,$J$1)=0,$J$1,MOD($J7+INDEX(_xlfn.TEXTSPLIT(F66,",",),0,1)+$J$1,$J$1))/2,0),ROUNDUP(IF(MOD(O$1+INDEX(_xlfn.TEXTSPLIT(F66,",",),0,2)+$J$1,$J$1)=0,$J$1,MOD(O$1+INDEX(_xlfn.TEXTSPLIT(F66,",",),0,2)+$J$1,$J$1))/2,0))} -> 8 | P7: {=INDEX($D$2:$H$6,ROUNDUP(IF(MOD($J7+INDEX(_xlfn.TEXTSPLIT(G66,",",),0,1)+$J$1,$J$1)=0,$J$1,MOD($J7+INDEX(_xlfn.TEXTSPLIT(G66,",",),0,1)+$J$1,$J$1))/2,0),ROUNDUP(IF(MOD(P$1+INDEX(_xlfn.TEXTSPLIT(G66,",",),0,2)+$J$1,$J$1)=0,$J$1,MOD(P$1+INDEX(_xlfn.TEXTSPLIT(G66,",",),0,2)+$J$1,$J$1))/2,0))} -> 8 | Q7: {=INDEX($D$2:$H$6,ROUNDUP(IF(MOD($J7+INDEX(_xlfn.TEXTSPLIT(H66,",",),0,1)+$J$1,$J$1)=0,$J$1,MOD($J7+INDEX(_xlfn.TEXTSPLIT(H66,",",),0,1)+$J$1,$J$1))/2,0),ROUNDUP(IF(MOD(Q$1+INDEX(_xlfn.TEXTSPLIT(H66,",",),0,2)+$J$1,$J$1)=0,$J$1,MOD(Q$1+INDEX(_xlfn.TEXTSPLIT(H66,",",),0,2)+$J$1,$J$1))/2,0))} -> 8 | R7: {=INDEX($D$2:$H$6,ROUNDUP(IF(MOD($J7+INDEX(_xlfn.TEXTSPLIT(I66,",",),0,1)+$J$1,$J$1)=0,$J$1,MOD($J7+INDEX(_xlfn.TEXTSPLIT(I66,",",),0,1)+$J$1,$J$1))/2,0),ROUNDUP(IF(MOD(R$1+INDEX(_xlfn.TEXTSPLIT(I66,",",),0,2)+$J$1,$J$1)=0,$J$1,MOD(R$1+INDEX(_xlfn.TEXTSPLIT(I66,",",),0,2)+$J$1,$J$1))/2,0))} -> 8 | ... T7: {=INDEX($D$2:$H$6,ROUNDUP(IF(MOD($J7+INDEX(_xlfn.TEXTSPLIT(K66,",",),0,1)+$J$1,$J$1)=0,$J$1,MOD($J7+INDEX(_xlfn.TEXTSPLIT(K66,",",),0,1)+$J$1,$J$1))/2,0),ROUNDUP(IF(MOD(T$1+INDEX(_xlfn.TEXTSPLIT(K66,",",),0,2)+$J$1,$J$1)=0,$J$1,MOD(T$1+INDEX(_xlfn.TEXTSPLIT(K66,",",),0,2)+$J$1,$J$1))/2,0))} -> 8 | AC7: 6 | AD7: {=INDEX($X$2:$AA$5,ROUNDUP(IF(MOD($AC7+INDEX(_xlfn.TEXTSPLIT(N66,",",),0,1)+$AC$1,$AC$1)=0,$AC$1,MOD($AC7+INDEX(_xlfn.TEXTSPLIT(N66,",",),0,1)+$AC$1,$AC$1))/2,0),ROUNDUP(IF(MOD(AD$1+INDEX(_xlfn.TEXTSPLIT(N66,",",),0,2)+$AC$1,$AC$1)=0,$AC$1,MOD(AD$1+INDEX(_xlfn.TEXTSPLIT(N66,",",),0,2)+$AC$1,$AC$1))/2,0))} -> -2 | AE7: {=INDEX($X$2:$AA$5,ROUNDUP(IF(MOD($AC7+INDEX(_xlfn.TEXTSPLIT(O66,",",),0,1)+$AC$1,$AC$1)=0,$AC$1,MOD($AC7+INDEX(_xlfn.TEXTSPLIT(O66,",",),0,1)+$AC$1,$AC$1))/2,0),ROUNDUP(IF(MOD(AE$1+INDEX(_xlfn.TEXTSPLIT(O66,",",),0,2)+$AC$1,$AC$1)=0,$AC$1,MOD(AE$1+INDEX(_xlfn.TEXTSPLIT(O66,",",),0,2)+$AC$1,$AC$1))/2,0))} -> -1 | AF7: {=INDEX($X$2:$AA$5,ROUNDUP(IF(MOD($AC7+INDEX(_xlfn.TEXTSPLIT(P66,",",),0,1)+$AC$1,$AC$1)=0,$AC$1,MOD($AC7+INDEX(_xlfn.TEXTSPLIT(P66,",",),0,1)+$AC$1,$AC$1))/2,0),ROUNDUP(IF(MOD(AF$1+INDEX(_xlfn.TEXTSPLIT(P66,",",),0,2)+$AC$1,$AC$1)=0,$AC$1,MOD(AF$1+INDEX(_xlfn.TEXTSPLIT(P66,",",),0,2)+$AC$1,$AC$1))/2,0))} -> -2 | AG7: {=INDEX($X$2:$AA$5,ROUNDUP(IF(MOD($AC7+INDEX(_xlfn.TEXTSPLIT(Q66,",",),0,1)+$AC$1,$AC$1)=0,$AC$1,MOD($AC7+INDEX(_xlfn.TEXTSPLIT(Q66,",",),0,1)+$AC$1,$AC$1))/2,0),ROUNDUP(IF(MOD(AG$1+INDEX(_xlfn.TEXTSPLIT(Q66,",",),0,2)+$AC$1,$AC$1)=0,$AC$1,MOD(AG$1+INDEX(_xlfn.TEXTSPLIT(Q66,",",),0,2)+$AC$1,$AC$1))/2,0))} -> 0 | AH7: {=INDEX($X$2:$AA$5,ROUNDUP(IF(MOD($AC7+INDEX(_xlfn.TEXTSPLIT(R66,",",),0,1)+$AC$1,$AC$1)=0,$AC$1,MOD($AC7+INDEX(_xlfn.TEXTSPLIT(R66,",",),0,1)+$AC$1,$AC$1))/2,0),ROUNDUP(IF(MOD(AH$1+INDEX(_xlfn.TEXTSPLIT(R66,",",),0,2)+$AC$1,$AC$1)=0,$AC$1,MOD(AH$1+INDEX(_xlfn.TEXTSPLIT(R66,",",),0,2)+$AC$1,$AC$1))/2,0))} -> -1 | AI7: {=INDEX($X$2:$AA$5,ROUNDUP(IF(MOD($AC7+INDEX(_xlfn.TEXTSPLIT(S66,",",),0,1)+$AC$1,$AC$1)=0,$AC$1,MOD($AC7+INDEX(_xlfn.TEXTSPLIT(S66,",",),0,1)+$AC$1,$AC$1))/2,0),ROUNDUP(IF(MOD(AI$1+INDEX(_xlfn.TEXTSPLIT(S66,",",),0,2)+$AC$1,$AC$1)=0,$AC$1,MOD(AI$1+INDEX(_xlfn.TEXTSPLIT(S66,",",),0,2)+$AC$1,$AC$1))/2,0))} -> -1 | AJ7: {=INDEX($X$2:$AA$5,ROUNDUP(IF(MOD($AC7+INDEX(_xlfn.TEXTSPLIT(T66,",",),0,1)+$AC$1,$AC$1)=0,$AC$1,MOD($AC7+INDEX(_xlfn.TEXTSPLIT(T66,",",),0,1)+$AC$1,$AC$1))/2,0),ROUNDUP(IF(MOD(AJ$1+INDEX(_xlfn.TEXTSPLIT(T66,",",),0,2)+$AC$1,$AC$1)=0,$AC$1,MOD(AJ$1+INDEX(_xlfn.TEXTSPLIT(T66,",",),0,2)+$AC$1,$AC$1))/2,0))} -> 0 | AK7: {=INDEX($X$2:$AA$5,ROUNDUP(IF(MOD($AC7+INDEX(_xlfn.TEXTSPLIT(U66,",",),0,1)+$AC$1,$AC$1)=0,$AC$1,MOD($AC7+INDEX(_xlfn.TEXTSPLIT(U66,",",),0,1)+$AC$1,$AC$1))/2,0),ROUNDUP(IF(MOD(AK$1+INDEX(_xlfn.TEXTSPLIT(U66,",",),0,2)+$AC$1,$AC$1)=0,$AC$1,MOD(AK$1+INDEX(_xlfn.TEXTSPLIT(U66,",",),0,2)+$AC$1,$AC$1))/2,0))} -> -1
C8: Land Percent | D8: =COUNTIF(B19:AO58,"<5") -> 326 | E8: =D8/(40*40) -> 0.20375 | J8: 7 | K8: {=INDEX($D$2:$H$6,ROUNDUP(IF(MOD($J8+INDEX(_xlfn.TEXTSPLIT(B67,",",),0,1)+$J$1,$J$1)=0,$J$1,MOD($J8+INDEX(_xlfn.TEXTSPLIT(B67,",",),0,1)+$J$1,$J$1))/2,0),ROUNDUP(IF(MOD(K$1+INDEX(_xlfn.TEXTSPLIT(B67,",",),0,2)+$J$1,$J$1)=0,$J$1,MOD(K$1+INDEX(_xlfn.TEXTSPLIT(B67,",",),0,2)+$J$1,$J$1))/2,0))} -> 8 | L8: {=INDEX($D$2:$H$6,ROUNDUP(IF(MOD($J8+INDEX(_xlfn.TEXTSPLIT(C67,",",),0,1)+$J$1,$J$1)=0,$J$1,MOD($J8+INDEX(_xlfn.TEXTSPLIT(C67,",",),0,1)+$J$1,$J$1))/2,0),ROUNDUP(IF(MOD(L$1+INDEX(_xlfn.TEXTSPLIT(C67,",",),0,2)+$J$1,$J$1)=0,$J$1,MOD(L$1+INDEX(_xlfn.TEXTSPLIT(C67,",",),0,2)+$J$1,$J$1))/2,0))} -> 4 | M8: {=INDEX($D$2:$H$6,ROUNDUP(IF(MOD($J8+INDEX(_xlfn.TEXTSPLIT(D67,",",),0,1)+$J$1,$J$1)=0,$J$1,MOD($J8+INDEX(_xlfn.TEXTSPLIT(D67,",",),0,1)+$J$1,$J$1))/2,0),ROUNDUP(IF(MOD(M$1+INDEX(_xlfn.TEXTSPLIT(D67,",",),0,2)+$J$1,$J$1)=0,$J$1,MOD(M$1+INDEX(_xlfn.TEXTSPLIT(D67,",",),0,2)+$J$1,$J$1))/2,0))} -> 8 | N8: {=INDEX($D$2:$H$6,ROUNDUP(IF(MOD($J8+INDEX(_xlfn.TEXTSPLIT(E67,",",),0,1)+$J$1,$J$1)=0,$J$1,MOD($J8+INDEX(_xlfn.TEXTSPLIT(E67,",",),0,1)+$J$1,$J$1))/2,0),ROUNDUP(IF(MOD(N$1+INDEX(_xlfn.TEXTSPLIT(E67,",",),0,2)+$J$1,$J$1)=0,$J$1,MOD(N$1+INDEX(_xlfn.TEXTSPLIT(E67,",",),0,2)+$J$1,$J$1))/2,0))} -> 8 | O8: {=INDEX($D$2:$H$6,ROUNDUP(IF(MOD($J8+INDEX(_xlfn.TEXTSPLIT(F67,",",),0,1)+$J$1,$J$1)=0,$J$1,MOD($J8+INDEX(_xlfn.TEXTSPLIT(F67,",",),0,1)+$J$1,$J$1))/2,0),ROUNDUP(IF(MOD(O$1+INDEX(_xlfn.TEXTSPLIT(F67,",",),0,2)+$J$1,$J$1)=0,$J$1,MOD(O$1+INDEX(_xlfn.TEXTSPLIT(F67,",",),0,2)+$J$1,$J$1))/2,0))} -> 8 | P8: {=INDEX($D$2:$H$6,ROUNDUP(IF(MOD($J8+INDEX(_xlfn.TEXTSPLIT(G67,",",),0,1)+$J$1,$J$1)=0,$J$1,MOD($J8+INDEX(_xlfn.TEXTSPLIT(G67,",",),0,1)+$J$1,$J$1))/2,0),ROUNDUP(IF(MOD(P$1+INDEX(_xlfn.TEXTSPLIT(G67,",",),0,2)+$J$1,$J$1)=0,$J$1,MOD(P$1+INDEX(_xlfn.TEXTSPLIT(G67,",",),0,2)+$J$1,$J$1))/2,0))} -> 8 | Q8: {=INDEX($D$2:$H$6,ROUNDUP(IF(MOD($J8+INDEX(_xlfn.TEXTSPLIT(H67,",",),0,1)+$J$1,$J$1)=0,$J$1,MOD($J8+INDEX(_xlfn.TEXTSPLIT(H67,",",),0,1)+$J$1,$J$1))/2,0),ROUNDUP(IF(MOD(Q$1+INDEX(_xlfn.TEXTSPLIT(H67,",",),0,2)+$J$1,$J$1)=0,$J$1,MOD(Q$1+INDEX(_xlfn.TEXTSPLIT(H67,",",),0,2)+$J$1,$J$1))/2,0))} -> 8 | R8: {=INDEX($D$2:$H$6,ROUNDUP(IF(MOD($J8+INDEX(_xlfn.TEXTSPLIT(I67,",",),0,1)+$J$1,$J$1)=0,$J$1,MOD($J8+INDEX(_xlfn.TEXTSPLIT(I67,",",),0,1)+$J$1,$J$1))/2,0),ROUNDUP(IF(MOD(R$1+INDEX(_xlfn.TEXTSPLIT(I67,",",),0,2)+$J$1,$J$1)=0,$J$1,MOD(R$1+INDEX(_xlfn.TEXTSPLIT(I67,",",),0,2)+$J$1,$J$1))/2,0))} -> 8 | ... T8: {=INDEX($D$2:$H$6,ROUNDUP(IF(MOD($J8+INDEX(_xlfn.TEXTSPLIT(K67,",",),0,1)+$J$1,$J$1)=0,$J$1,MOD($J8+INDEX(_xlfn.TEXTSPLIT(K67,",",),0,1)+$J$1,$J$1))/2,0),ROUNDUP(IF(MOD(T$1+INDEX(_xlfn.TEXTSPLIT(K67,",",),0,2)+$J$1,$J$1)=0,$J$1,MOD(T$1+INDEX(_xlfn.TEXTSPLIT(K67,",",),0,2)+$J$1,$J$1))/2,0))} -> 8 | U8: 1 | V8: ⤴ | AC8: 7 | AD8: {=INDEX($X$2:$AA$5,ROUNDUP(IF(MOD($AC8+INDEX(_xlfn.TEXTSPLIT(N67,",",),0,1)+$AC$1,$AC$1)=0,$AC$1,MOD($AC8+INDEX(_xlfn.TEXTSPLIT(N67,",",),0,1)+$AC$1,$AC$1))/2,0),ROUNDUP(IF(MOD(AD$1+INDEX(_xlfn.TEXTSPLIT(N67,",",),0,2)+$AC$1,$AC$1)=0,$AC$1,MOD(AD$1+INDEX(_xlfn.TEXTSPLIT(N67,",",),0,2)+$AC$1,$AC$1))/2,0))} -> -1 | AE8: {=INDEX($X$2:$AA$5,ROUNDUP(IF(MOD($AC8+INDEX(_xlfn.TEXTSPLIT(O67,",",),0,1)+$AC$1,$AC$1)=0,$AC$1,MOD($AC8+INDEX(_xlfn.TEXTSPLIT(O67,",",),0,1)+$AC$1,$AC$1))/2,0),ROUNDUP(IF(MOD(AE$1+INDEX(_xlfn.TEXTSPLIT(O67,",",),0,2)+$AC$1,$AC$1)=0,$AC$1,MOD(AE$1+INDEX(_xlfn.TEXTSPLIT(O67,",",),0,2)+$AC$1,$AC$1))/2,0))} -> -1 | AF8: {=INDEX($X$2:$AA$5,ROUNDUP(IF(MOD($AC8+INDEX(_xlfn.TEXTSPLIT(P67,",",),0,1)+$AC$1,$AC$1)=0,$AC$1,MOD($AC8+INDEX(_xlfn.TEXTSPLIT(P67,",",),0,1)+$AC$1,$AC$1))/2,0),ROUNDUP(IF(MOD(AF$1+INDEX(_xlfn.TEXTSPLIT(P67,",",),0,2)+$AC$1,$AC$1)=0,$AC$1,MOD(AF$1+INDEX(_xlfn.TEXTSPLIT(P67,",",),0,2)+$AC$1,$AC$1))/2,0))} -> -1 | AG8: {=INDEX($X$2:$AA$5,ROUNDUP(IF(MOD($AC8+INDEX(_xlfn.TEXTSPLIT(Q67,",",),0,1)+$AC$1,$AC$1)=0,$AC$1,MOD($AC8+INDEX(_xlfn.TEXTSPLIT(Q67,",",),0,1)+$AC$1,$AC$1))/2,0),ROUNDUP(IF(MOD(AG$1+INDEX(_xlfn.TEXTSPLIT(Q67,",",),0,2)+$AC$1,$AC$1)=0,$AC$1,MOD(AG$1+INDEX(_xlfn.TEXTSPLIT(Q67,",",),0,2)+$AC$1,$AC$1))/2,0))} -> -1 | AH8: {=INDEX($X$2:$AA$5,ROUNDUP(IF(MOD($AC8+INDEX(_xlfn.TEXTSPLIT(R67,",",),0,1)+$AC$1,$AC$1)=0,$AC$1,MOD($AC8+INDEX(_xlfn.TEXTSPLIT(R67,",",),0,1)+$AC$1,$AC$1))/2,0),ROUNDUP(IF(MOD(AH$1+INDEX(_xlfn.TEXTSPLIT(R67,",",),0,2)+$AC$1,$AC$1)=0,$AC$1,MOD(AH$1+INDEX(_xlfn.TEXTSPLIT(R67,",",),0,2)+$AC$1,$AC$1))/2,0))} -> -1 | AI8: {=INDEX($X$2:$AA$5,ROUNDUP(IF(MOD($AC8+INDEX(_xlfn.TEXTSPLIT(S67,",",),0,1)+$AC$1,$AC$1)=0,$AC$1,MOD($AC8+INDEX(_xlfn.TEXTSPLIT(S67,",",),0,1)+$AC$1,$AC$1))/2,0),ROUNDUP(IF(MOD(AI$1+INDEX(_xlfn.TEXTSPLIT(S67,",",),0,2)+$AC$1,$AC$1)=0,$AC$1,MOD(AI$1+INDEX(_xlfn.TEXTSPLIT(S67,",",),0,2)+$AC$1,$AC$1))/2,0))} -> 0 | AJ8: {=INDEX($X$2:$AA$5,ROUNDUP(IF(MOD($AC8+INDEX(_xlfn.TEXTSPLIT(T67,",",),0,1)+$AC$1,$AC$1)=0,$AC$1,MOD($AC8+INDEX(_xlfn.TEXTSPLIT(T67,",",),0,1)+$AC$1,$AC$1))/2,0),ROUNDUP(IF(MOD(AJ$1+INDEX(_xlfn.TEXTSPLIT(T67,",",),0,2)+$AC$1,$AC$1)=0,$AC$1,MOD(AJ$1+INDEX(_xlfn.TEXTSPLIT(T67,",",),0,2)+$AC$1,$AC$1))/2,0))} -> -3 | AK8: {=INDEX($X$2:$AA$5,ROUNDUP(IF(MOD($AC8+INDEX(_xlfn.TEXTSPLIT(U67,",",),0,1)+$AC$1,$AC$1)=0,$AC$1,MOD($AC8+INDEX(_xlfn.TEXTSPLIT(U67,",",),0,1)+$AC$1,$AC$1))/2,0),ROUNDUP(IF(MOD(AK$1+INDEX(_xlfn.TEXTSPLIT(U67,",",),0,2)+$AC$1,$AC$1)=0,$AC$1,MOD(AK$1+INDEX(_xlfn.TEXTSPLIT(U67,",",),0,2)+$AC$1,$AC$1))/2,0))} -> -3
C9: Ft^2 | D9: =#REF! -> #REF! | E9: =E8*D9 -> #REF! | F9: =E9/D8 -> #REF! | J9: 8 | K9: {=INDEX($D$2:$H$6,ROUNDUP(IF(MOD($J9+INDEX(_xlfn.TEXTSPLIT(B68,",",),0,1)+$J$1,$J$1)=0,$J$1,MOD($J9+INDEX(_xlfn.TEXTSPLIT(B68,",",),0,1)+$J$1,$J$1))/2,0),ROUNDUP(IF(MOD(K$1+INDEX(_xlfn.TEXTSPLIT(B68,",",),0,2)+$J$1,$J$1)=0,$J$1,MOD(K$1+INDEX(_xlfn.TEXTSPLIT(B68,",",),0,2)+$J$1,$J$1))/2,0))} -> 4 | L9: {=INDEX($D$2:$H$6,ROUNDUP(IF(MOD($J9+INDEX(_xlfn.TEXTSPLIT(C68,",",),0,1)+$J$1,$J$1)=0,$J$1,MOD($J9+INDEX(_xlfn.TEXTSPLIT(C68,",",),0,1)+$J$1,$J$1))/2,0),ROUNDUP(IF(MOD(L$1+INDEX(_xlfn.TEXTSPLIT(C68,",",),0,2)+$J$1,$J$1)=0,$J$1,MOD(L$1+INDEX(_xlfn.TEXTSPLIT(C68,",",),0,2)+$J$1,$J$1))/2,0))} -> 4 | M9: {=INDEX($D$2:$H$6,ROUNDUP(IF(MOD($J9+INDEX(_xlfn.TEXTSPLIT(D68,",",),0,1)+$J$1,$J$1)=0,$J$1,MOD($J9+INDEX(_xlfn.TEXTSPLIT(D68,",",),0,1)+$J$1,$J$1))/2,0),ROUNDUP(IF(MOD(M$1+INDEX(_xlfn.TEXTSPLIT(D68,",",),0,2)+$J$1,$J$1)=0,$J$1,MOD(M$1+INDEX(_xlfn.TEXTSPLIT(D68,",",),0,2)+$J$1,$J$1))/2,0))} -> 8 | N9: {=INDEX($D$2:$H$6,ROUNDUP(IF(MOD($J9+INDEX(_xlfn.TEXTSPLIT(E68,",",),0,1)+$J$1,$J$1)=0,$J$1,MOD($J9+INDEX(_xlfn.TEXTSPLIT(E68,",",),0,1)+$J$1,$J$1))/2,0),ROUNDUP(IF(MOD(N$1+INDEX(_xlfn.TEXTSPLIT(E68,",",),0,2)+$J$1,$J$1)=0,$J$1,MOD(N$1+INDEX(_xlfn.TEXTSPLIT(E68,",",),0,2)+$J$1,$J$1))/2,0))} -> 8 | O9: {=INDEX($D$2:$H$6,ROUNDUP(IF(MOD($J9+INDEX(_xlfn.TEXTSPLIT(F68,",",),0,1)+$J$1,$J$1)=0,$J$1,MOD($J9+INDEX(_xlfn.TEXTSPLIT(F68,",",),0,1)+$J$1,$J$1))/2,0),ROUNDUP(IF(MOD(O$1+INDEX(_xlfn.TEXTSPLIT(F68,",",),0,2)+$J$1,$J$1)=0,$J$1,MOD(O$1+INDEX(_xlfn.TEXTSPLIT(F68,",",),0,2)+$J$1,$J$1))/2,0))} -> 8 | P9: {=INDEX($D$2:$H$6,ROUNDUP(IF(MOD($J9+INDEX(_xlfn.TEXTSPLIT(G68,",",),0,1)+$J$1,$J$1)=0,$J$1,MOD($J9+INDEX(_xlfn.TEXTSPLIT(G68,",",),0,1)+$J$1,$J$1))/2,0),ROUNDUP(IF(MOD(P$1+INDEX(_xlfn.TEXTSPLIT(G68,",",),0,2)+$J$1,$J$1)=0,$J$1,MOD(P$1+INDEX(_xlfn.TEXTSPLIT(G68,",",),0,2)+$J$1,$J$1))/2,0))} -> 8 | Q9: {=INDEX($D$2:$H$6,ROUNDUP(IF(MOD($J9+INDEX(_xlfn.TEXTSPLIT(H68,",",),0,1)+$J$1,$J$1)=0,$J$1,MOD($J9+INDEX(_xlfn.TEXTSPLIT(H68,",",),0,1)+$J$1,$J$1))/2,0),ROUNDUP(IF(MOD(Q$1+INDEX(_xlfn.TEXTSPLIT(H68,",",),0,2)+$J$1,$J$1)=0,$J$1,MOD(Q$1+INDEX(_xlfn.TEXTSPLIT(H68,",",),0,2)+$J$1,$J$1))/2,0))} -> 8 | R9: {=INDEX($D$2:$H$6,ROUNDUP(IF(MOD($J9+INDEX(_xlfn.TEXTSPLIT(I68,",",),0,1)+$J$1,$J$1)=0,$J$1,MOD($J9+INDEX(_xlfn.TEXTSPLIT(I68,",",),0,1)+$J$1,$J$1))/2,0),ROUNDUP(IF(MOD(R$1+INDEX(_xlfn.TEXTSPLIT(I68,",",),0,2)+$J$1,$J$1)=0,$J$1,MOD(R$1+INDEX(_xlfn.TEXTSPLIT(I68,",",),0,2)+$J$1,$J$1))/2,0))} -> 8 | ... T9: {=INDEX($D$2:$H$6,ROUNDUP(IF(MOD($J9+INDEX(_xlfn.TEXTSPLIT(K68,",",),0,1)+$J$1,$J$1)=0,$J$1,MOD($J9+INDEX(_xlfn.TEXTSPLIT(K68,",",),0,1)+$J$1,$J$1))/2,0),ROUNDUP(IF(MOD(T$1+INDEX(_xlfn.TEXTSPLIT(K68,",",),0,2)+$J$1,$J$1)=0,$J$1,MOD(T$1+INDEX(_xlfn.TEXTSPLIT(K68,",",),0,2)+$J$1,$J$1))/2,0))} -> 8 | U9: 2 | V9: ↪ | AC9: 8 | AD9: {=INDEX($X$2:$AA$5,ROUNDUP($AC9/2,0),ROUNDUP(IF(MOD(AD$1+INDEX(_xlfn.TEXTSPLIT(N68,",",),0,2)+$AC$1,$AC$1)=0,$AC$1,MOD(AD$1+INDEX(_xlfn.TEXTSPLIT(N68,",",),0,2)+$AC$1,$AC$1))/2,0))} -> -3 | AE9: {=INDEX($X$2:$AA$5,ROUNDUP($AC9/2,0),ROUNDUP(IF(MOD(AE$1+INDEX(_xlfn.TEXTSPLIT(O68,",",),0,2)+$AC$1,$AC$1)=0,$AC$1,MOD(AE$1+INDEX(_xlfn.TEXTSPLIT(O68,",",),0,2)+$AC$1,$AC$1))/2,0))} -> -1 | AF9: {=INDEX($X$2:$AA$5,ROUNDUP($AC9/2,0),ROUNDUP(IF(MOD(AF$1+INDEX(_xlfn.TEXTSPLIT(P68,",",),0,2)+$AC$1,$AC$1)=0,$AC$1,MOD(AF$1+INDEX(_xlfn.TEXTSPLIT(P68,",",),0,2)+$AC$1,$AC$1))/2,0))} -> -1 | AG9: {=INDEX($X$2:$AA$5,ROUNDUP($AC9/2,0),ROUNDUP(IF(MOD(AG$1+INDEX(_xlfn.TEXTSPLIT(Q68,",",),0,2)+$AC$1,$AC$1)=0,$AC$1,MOD(AG$1+INDEX(_xlfn.TEXTSPLIT(Q68,",",),0,2)+$AC$1,$AC$1))/2,0))} -> 0 | AH9: {=INDEX($X$2:$AA$5,ROUNDUP($AC9/2,0),ROUNDUP(IF(MOD(AH$1+INDEX(_xlfn.TEXTSPLIT(R68,",",),0,2)+$AC$1,$AC$1)=0,$AC$1,MOD(AH$1+INDEX(_xlfn.TEXTSPLIT(R68,",",),0,2)+$AC$1,$AC$1))/2,0))} -> -1 | AI9: {=INDEX($X$2:$AA$5,ROUNDUP($AC9/2,0),ROUNDUP(IF(MOD(AI$1+INDEX(_xlfn.TEXTSPLIT(S68,",",),0,2)+$AC$1,$AC$1)=0,$AC$1,MOD(AI$1+INDEX(_xlfn.TEXTSPLIT(S68,",",),0,2)+$AC$1,$AC$1))/2,0))} -> 0 | AJ9: {=INDEX($X$2:$AA$5,ROUNDUP($AC9/2,0),ROUNDUP(IF(MOD(AJ$1+INDEX(_xlfn.TEXTSPLIT(T68,",",),0,2)+$AC$1,$AC$1)=0,$AC$1,MOD(AJ$1+INDEX(_xlfn.TEXTSPLIT(T68,",",),0,2)+$AC$1,$AC$1))/2,0))} -> 0 | AK9: {=INDEX($X$2:$AA$5,ROUNDUP($AC9/2,0),ROUNDUP(IF(MOD(AK$1+INDEX(_xlfn.TEXTSPLIT(U68,",",),0,2)+$AC$1,$AC$1)=0,$AC$1,MOD(AK$1+INDEX(_xlfn.TEXTSPLIT(U68,",",),0,2)+$AC$1,$AC$1))/2,0))} -> -1
J10: 9 | K10: {=INDEX($D$2:$H$6,ROUNDUP(IF(MOD($J10+INDEX(_xlfn.TEXTSPLIT(B69,",",),0,1)+$J$1,$J$1)=0,$J$1,MOD($J10+INDEX(_xlfn.TEXTSPLIT(B69,",",),0,1)+$J$1,$J$1))/2,0),ROUNDUP(IF(MOD(K$1+INDEX(_xlfn.TEXTSPLIT(B69,",",),0,2)+$J$1,$J$1)=0,$J$1,MOD(K$1+INDEX(_xlfn.TEXTSPLIT(B69,",",),0,2)+$J$1,$J$1))/2,0))} -> 8 | L10: {=INDEX($D$2:$H$6,ROUNDUP(IF(MOD($J10+INDEX(_xlfn.TEXTSPLIT(C69,",",),0,1)+$J$1,$J$1)=0,$J$1,MOD($J10+INDEX(_xlfn.TEXTSPLIT(C69,",",),0,1)+$J$1,$J$1))/2,0),ROUNDUP(IF(MOD(L$1+INDEX(_xlfn.TEXTSPLIT(C69,",",),0,2)+$J$1,$J$1)=0,$J$1,MOD(L$1+INDEX(_xlfn.TEXTSPLIT(C69,",",),0,2)+$J$1,$J$1))/2,0))} -> 8 | M10: {=INDEX($D$2:$H$6,ROUNDUP(IF(MOD($J10+INDEX(_xlfn.TEXTSPLIT(D69,",",),0,1)+$J$1,$J$1)=0,$J$1,MOD($J10+INDEX(_xlfn.TEXTSPLIT(D69,",",),0,1)+$J$1,$J$1))/2,0),ROUNDUP(IF(MOD(M$1+INDEX(_xlfn.TEXTSPLIT(D69,",",),0,2)+$J$1,$J$1)=0,$J$1,MOD(M$1+INDEX(_xlfn.TEXTSPLIT(D69,",",),0,2)+$J$1,$J$1))/2,0))} -> 4 | N10: {=INDEX($D$2:$H$6,ROUNDUP(IF(MOD($J10+INDEX(_xlfn.TEXTSPLIT(E69,",",),0,1)+$J$1,$J$1)=0,$J$1,MOD($J10+INDEX(_xlfn.TEXTSPLIT(E69,",",),0,1)+$J$1,$J$1))/2,0),ROUNDUP(IF(MOD(N$1+INDEX(_xlfn.TEXTSPLIT(E69,",",),0,2)+$J$1,$J$1)=0,$J$1,MOD(N$1+INDEX(_xlfn.TEXTSPLIT(E69,",",),0,2)+$J$1,$J$1))/2,0))} -> 4 | O10: {=INDEX($D$2:$H$6,ROUNDUP(IF(MOD($J10+INDEX(_xlfn.TEXTSPLIT(F69,",",),0,1)+$J$1,$J$1)=0,$J$1,MOD($J10+INDEX(_xlfn.TEXTSPLIT(F69,",",),0,1)+$J$1,$J$1))/2,0),ROUNDUP(IF(MOD(O$1+INDEX(_xlfn.TEXTSPLIT(F69,",",),0,2)+$J$1,$J$1)=0,$J$1,MOD(O$1+INDEX(_xlfn.TEXTSPLIT(F69,",",),0,2)+$J$1,$J$1))/2,0))} -> 8 | P10: {=INDEX($D$2:$H$6,ROUNDUP(IF(MOD($J10+INDEX(_xlfn.TEXTSPLIT(G69,",",),0,1)+$J$1,$J$1)=0,$J$1,MOD($J10+INDEX(_xlfn.TEXTSPLIT(G69,",",),0,1)+$J$1,$J$1))/2,0),ROUNDUP(IF(MOD(P$1+INDEX(_xlfn.TEXTSPLIT(G69,",",),0,2)+$J$1,$J$1)=0,$J$1,MOD(P$1+INDEX(_xlfn.TEXTSPLIT(G69,",",),0,2)+$J$1,$J$1))/2,0))} -> 8 | Q10: {=INDEX($D$2:$H$6,ROUNDUP(IF(MOD($J10+INDEX(_xlfn.TEXTSPLIT(H69,",",),0,1)+$J$1,$J$1)=0,$J$1,MOD($J10+INDEX(_xlfn.TEXTSPLIT(H69,",",),0,1)+$J$1,$J$1))/2,0),ROUNDUP(IF(MOD(Q$1+INDEX(_xlfn.TEXTSPLIT(H69,",",),0,2)+$J$1,$J$1)=0,$J$1,MOD(Q$1+INDEX(_xlfn.TEXTSPLIT(H69,",",),0,2)+$J$1,$J$1))/2,0))} -> 8 | R10: {=INDEX($D$2:$H$6,ROUNDUP(IF(MOD($J10+INDEX(_xlfn.TEXTSPLIT(I69,",",),0,1)+$J$1,$J$1)=0,$J$1,MOD($J10+INDEX(_xlfn.TEXTSPLIT(I69,",",),0,1)+$J$1,$J$1))/2,0),ROUNDUP(IF(MOD(R$1+INDEX(_xlfn.TEXTSPLIT(I69,",",),0,2)+$J$1,$J$1)=0,$J$1,MOD(R$1+INDEX(_xlfn.TEXTSPLIT(I69,",",),0,2)+$J$1,$J$1))/2,0))} -> 8 | ... T10: {=INDEX($D$2:$H$6,ROUNDUP(IF(MOD($J10+INDEX(_xlfn.TEXTSPLIT(K69,",",),0,1)+$J$1,$J$1)=0,$J$1,MOD($J10+INDEX(_xlfn.TEXTSPLIT(K69,",",),0,1)+$J$1,$J$1))/2,0),ROUNDUP(IF(MOD(T$1+INDEX(_xlfn.TEXTSPLIT(K69,",",),0,2)+$J$1,$J$1)=0,$J$1,MOD(T$1+INDEX(_xlfn.TEXTSPLIT(K69,",",),0,2)+$J$1,$J$1))/2,0))} -> 8 | U10: 3 | V10: ⤵
J11: 10 | K11: {=INDEX($D$2:$H$6,ROUNDUP($J11/2,0),ROUNDUP(IF(MOD(K$1+INDEX(_xlfn.TEXTSPLIT(B70,",",),0,2)+$J$1,$J$1)=0,$J$1,MOD(K$1+INDEX(_xlfn.TEXTSPLIT(B70,",",),0,2)+$J$1,$J$1))/2,0))} -> 8 | L11: {=INDEX($D$2:$H$6,ROUNDUP($J11/2,0),ROUNDUP(IF(MOD(L$1+INDEX(_xlfn.TEXTSPLIT(C70,",",),0,2)+$J$1,$J$1)=0,$J$1,MOD(L$1+INDEX(_xlfn.TEXTSPLIT(C70,",",),0,2)+$J$1,$J$1))/2,0))} -> 4 | M11: {=INDEX($D$2:$H$6,ROUNDUP($J11/2,0),ROUNDUP(IF(MOD(M$1+INDEX(_xlfn.TEXTSPLIT(D70,",",),0,2)+$J$1,$J$1)=0,$J$1,MOD(M$1+INDEX(_xlfn.TEXTSPLIT(D70,",",),0,2)+$J$1,$J$1))/2,0))} -> 8 | N11: {=INDEX($D$2:$H$6,ROUNDUP($J11/2,0),ROUNDUP(IF(MOD(N$1+INDEX(_xlfn.TEXTSPLIT(E70,",",),0,2)+$J$1,$J$1)=0,$J$1,MOD(N$1+INDEX(_xlfn.TEXTSPLIT(E70,",",),0,2)+$J$1,$J$1))/2,0))} -> 4 | O11: {=INDEX($D$2:$H$6,ROUNDUP($J11/2,0),ROUNDUP(IF(MOD(O$1+INDEX(_xlfn.TEXTSPLIT(F70,",",),0,2)+$J$1,$J$1)=0,$J$1,MOD(O$1+INDEX(_xlfn.TEXTSPLIT(F70,",",),0,2)+$J$1,$J$1))/2,0))} -> 4 | P11: {=INDEX($D$2:$H$6,ROUNDUP($J11/2,0),ROUNDUP(IF(MOD(P$1+INDEX(_xlfn.TEXTSPLIT(G70,",",),0,2)+$J$1,$J$1)=0,$J$1,MOD(P$1+INDEX(_xlfn.TEXTSPLIT(G70,",",),0,2)+$J$1,$J$1))/2,0))} -> 8 | Q11: {=INDEX($D$2:$H$6,ROUNDUP($J11/2,0),ROUNDUP(IF(MOD(Q$1+INDEX(_xlfn.TEXTSPLIT(H70,",",),0,2)+$J$1,$J$1)=0,$J$1,MOD(Q$1+INDEX(_xlfn.TEXTSPLIT(H70,",",),0,2)+$J$1,$J$1))/2,0))} -> 8 | R11: {=INDEX($D$2:$H$6,ROUNDUP($J11/2,0),ROUNDUP(IF(MOD(R$1+INDEX(_xlfn.TEXTSPLIT(I70,",",),0,2)+$J$1,$J$1)=0,$J$1,MOD(R$1+INDEX(_xlfn.TEXTSPLIT(I70,",",),0,2)+$J$1,$J$1))/2,0))} -> 8 | ... T11: {=INDEX($D$2:$H$6,ROUNDUP($J11/2,0),ROUNDUP(IF(MOD(T$1+INDEX(_xlfn.TEXTSPLIT(K70,",",),0,2)+$J$1,$J$1)=0,$J$1,MOD(T$1+INDEX(_xlfn.TEXTSPLIT(K70,",",),0,2)+$J$1,$J$1))/2,0))} -> 8 | U11: 0 | V11: ↩
B13: =IF(B14="","",_xlfn.TEXTJOIN(", ",RANDBETWEEN(1,40),RANDBETWEEN(1,40))) -> 18 | C13: =IF(C14="","",_xlfn.TEXTJOIN(", ",RANDBETWEEN(1,40),RANDBETWEEN(1,40))) -> 9 | D13: =IF(D14="","",_xlfn.TEXTJOIN(", ",RANDBETWEEN(1,40),RANDBETWEEN(1,40))) -> 31 | E13: =IF(E14="","",_xlfn.TEXTJOIN(", ",RANDBETWEEN(1,40),RANDBETWEEN(1,40))) -> 21 | F13: =IF(F14="","",_xlfn.TEXTJOIN(", ",RANDBETWEEN(1,40),RANDBETWEEN(1,40))) -> 31 | G13: =IF(G14="","",_xlfn.TEXTJOIN(", ",RANDBETWEEN(1,40),RANDBETWEEN(1,40))) -> 32 | H13: =IF(H14="","",_xlfn.TEXTJOIN(", ",RANDBETWEEN(1,40),RANDBETWEEN(1,40))) -> 20 | I13: =IF(I14="","",_xlfn.TEXTJOIN(", ",RANDBETWEEN(1,40),RANDBETWEEN(1,40))) -> 37 | ... M13: =IF(M14="","",_xlfn.TEXTJOIN(", ",RANDBETWEEN(1,40),RANDBETWEEN(1,40))) -> 7 | N13: =IF(N14="","",JOIN(", ",RANDBETWEEN(1,40),RANDBETWEEN(1,40))) | O13: =IF(O14="","",JOIN(", ",RANDBETWEEN(1,40),RANDBETWEEN(1,40))) | P13: =IF(P14="","",JOIN(", ",RANDBETWEEN(1,40),RANDBETWEEN(1,40))) | Q13: =IF(Q14="","",JOIN(", ",RANDBETWEEN(1,40),RANDBETWEEN(1,40))) | R13: =IF(R14="","",JOIN(", ",RANDBETWEEN(1,40),RANDBETWEEN(1,40))) | S13: =IF(S14="","",JOIN(", ",RANDBETWEEN(1,40),RANDBETWEEN(1,40))) | T13: =IF(T14="","",JOIN(", ",RANDBETWEEN(1,40),RANDBETWEEN(1,40))) | U13: =IF(U14="","",JOIN(", ",RANDBETWEEN(1,40),RANDBETWEEN(1,40))) | ... X13: =IF(X14="","",JOIN(", ",RANDBETWEEN(1,40),RANDBETWEEN(1,40)))
A14: 12 | B14: =IF(B15>$A$14,"",B15) -> 1 | C14: =IF(C15>$A$14,"",C15) -> 2 | D14: =IF(D15>$A$14,"",D15) -> 3 | E14: =IF(E15>$A$14,"",E15) -> 4 | F14: =IF(F15>$A$14,"",F15) -> 5 | G14: =IF(G15>$A$14,"",G15) -> 6 | H14: =IF(H15>$A$14,"",H15) -> 7 | I14: =IF(I15>$A$14,"",I15) -> 8 | ... X14: =IF(X15>$A$14,"",X15)
A15: =23*A16 -> #REF! | B15: 1 | C15: 2 | D15: 3 | E15: 4 | F15: 5 | G15: 6 | H15: 7 | I15: 8 | J15: 9 | K15: 10 | L15: 11 | M15: 12 | N15: 13 | O15: 14 | P15: 15 | Q15: 16 | R15: 17 | S15: 18 | T15: 19 | U15: 20 | V15: 21 | W15: 22 | X15: 23
A16: =E9/#REF! -> #REF!
A18: 40 | B18: 1 | C18: 2 | D18: 3 | E18: 4 | F18: 5 | G18: 6 | H18: 7 | I18: 8 | J18: 9 | K18: 10 | L18: 11 | M18: 12 | N18: 13 | O18: 14 | P18: 15 | Q18: 16 | R18: 17 | S18: 18 | T18: 19 | U18: 20 | V18: 21 | W18: 22 | X18: 23 | Y18: 24 | Z18: 25 | AA18: 26 | AB18: 27 | AC18: 28 | AD18: 29 | AE18: 30 | AF18: 31 | AG18: 32 | AH18: 33 | AI18: 34 | AJ18: 35 | AK18: 36 | AL18: 37 | AM18: 38 | AN18: 39 | AO18: 40
A19: 1 | B19: {=(INDEX($K$2:$T$11,ROUNDUP($A19/4,0),ROUNDUP(IF(MOD(B$18+INDEX(_xlfn.TEXTSPLIT(B74,",",),0,2)+$A$18,$A$18)=0,$A$18,MOD(B$18+INDEX(_xlfn.TEXTSPLIT(B74,",",),0,2)+$A$18,$A$18))/4,0)))+(INDEX($AD$2:$AK$9,ROUNDUP($A19/5,0),ROUNDUP(IF(MOD(B$18+INDEX(_xlfn.TEXTSPLIT(B117,",",),0,2)+$A$18,$A$18)=0,$A$18,MOD(B$18+INDEX(_xlfn.TEXTSPLIT(B117,",",),0,2)+$A$18,$A$18))/5,0)))} -> 6 | C19: {=(INDEX($K$2:$T$11,ROUNDUP($A19/4,0),ROUNDUP(IF(MOD(C$18+INDEX(_xlfn.TEXTSPLIT(C74,",",),0,2)+$A$18,$A$18)=0,$A$18,MOD(C$18+INDEX(_xlfn.TEXTSPLIT(C74,",",),0,2)+$A$18,$A$18))/4,0)))+(INDEX($AD$2:$AK$9,ROUNDUP($A19/5,0),ROUNDUP(IF(MOD(C$18+INDEX(_xlfn.TEXTSPLIT(C117,",",),0,2)+$A$18,$A$18)=0,$A$18,MOD(C$18+INDEX(_xlfn.TEXTSPLIT(C117,",",),0,2)+$A$18,$A$18))/5,0)))} -> 2 | D19: {=(INDEX($K$2:$T$11,ROUNDUP($A19/4,0),ROUNDUP(IF(MOD(D$18+INDEX(_xlfn.TEXTSPLIT(D74,",",),0,2)+$A$18,$A$18)=0,$A$18,MOD(D$18+INDEX(_xlfn.TEXTSPLIT(D74,",",),0,2)+$A$18,$A$18))/4,0)))+(INDEX($AD$2:$AK$9,ROUNDUP($A19/5,0),ROUNDUP(IF(MOD(D$18+INDEX(_xlfn.TEXTSPLIT(D117,",",),0,2)+$A$18,$A$18)=0,$A$18,MOD(D$18+INDEX(_xlfn.TEXTSPLIT(D117,",",),0,2)+$A$18,$A$18))/5,0)))} -> 2 | E19: {=(INDEX($K$2:$T$11,ROUNDUP($A19/4,0),ROUNDUP(IF(MOD(E$18+INDEX(_xlfn.TEXTSPLIT(E74,",",),0,2)+$A$18,$A$18)=0,$A$18,MOD(E$18+INDEX(_xlfn.TEXTSPLIT(E74,",",),0,2)+$A$18,$A$18))/4,0)))+(INDEX($AD$2:$AK$9,ROUNDUP($A19/5,0),ROUNDUP(IF(MOD(E$18+INDEX(_xlfn.TEXTSPLIT(E117,",",),0,2)+$A$18,$A$18)=0,$A$18,MOD(E$18+INDEX(_xlfn.TEXTSPLIT(E117,",",),0,2)+$A$18,$A$18))/5,0)))} -> 2 | F19: {=(INDEX($K$2:$T$11,ROUNDUP($A19/4,0),ROUNDUP(IF(MOD(F$18+INDEX(_xlfn.TEXTSPLIT(F74,",",),0,2)+$A$18,$A$18)=0,$A$18,MOD(F$18+INDEX(_xlfn.TEXTSPLIT(F74,",",),0,2)+$A$18,$A$18))/4,0)))+(INDEX($AD$2:$AK$9,ROUNDUP($A19/5,0),ROUNDUP(IF(MOD(F$18+INDEX(_xlfn.TEXTSPLIT(F117,",",),0,2)+$A$18,$A$18)=0,$A$18,MOD(F$18+INDEX(_xlfn.TEXTSPLIT(F117,",",),0,2)+$A$18,$A$18))/5,0)))} -> 6 | G19: {=(INDEX($K$2:$T$11,ROUNDUP($A19/4,0),ROUNDUP(IF(MOD(G$18+INDEX(_xlfn.TEXTSPLIT(G74,",",),0,2)+$A$18,$A$18)=0,$A$18,MOD(G$18+INDEX(_xlfn.TEXTSPLIT(G74,",",),0,2)+$A$18,$A$18))/4,0)))+(INDEX($AD$2:$AK$9,ROUNDUP($A19/5,0),ROUNDUP(IF(MOD(G$18+INDEX(_xlfn.TEXTSPLIT(G117,",",),0,2)+$A$18,$A$18)=0,$A$18,MOD(G$18+INDEX(_xlfn.TEXTSPLIT(G117,",",),0,2)+$A$18,$A$18))/5,0)))} -> 5 | H19: {=(INDEX($K$2:$T$11,ROUNDUP($A19/4,0),ROUNDUP(IF(MOD(H$18+INDEX(_xlfn.TEXTSPLIT(H74,",",),0,2)+$A$18,$A$18)=0,$A$18,MOD(H$18+INDEX(_xlfn.TEXTSPLIT(H74,",",),0,2)+$A$18,$A$18))/4,0)))+(INDEX($AD$2:$AK$9,ROUNDUP($A19/5,0),ROUNDUP(IF(MOD(H$18+INDEX(_xlfn.TEXTSPLIT(H117,",",),0,2)+$A$18,$A$18)=0,$A$18,MOD(H$18+INDEX(_xlfn.TEXTSPLIT(H117,",",),0,2)+$A$18,$A$18))/5,0)))} -> 5 | I19: {=(INDEX($K$2:$T$11,ROUNDUP($A19/4,0),ROUNDUP(IF(MOD(I$18+INDEX(_xlfn.TEXTSPLIT(I74,",",),0,2)+$A$18,$A$18)=0,$A$18,MOD(I$18+INDEX(_xlfn.TEXTSPLIT(I74,",",),0,2)+$A$18,$A$18))/4,0)))+(INDEX($AD$2:$AK$9,ROUNDUP($A19/5,0),ROUNDUP(IF(MOD(I$18+INDEX(_xlfn.TEXTSPLIT(I117,",",),0,2)+$A$18,$A$18)=0,$A$18,MOD(I$18+INDEX(_xlfn.TEXTSPLIT(I117,",",),0,2)+$A$18,$A$18))/5,0)))} -> 5 | ... AO19: {=(INDEX($K$2:$T$11,ROUNDUP($A19/4,0),ROUNDUP(IF(MOD(AO$18+INDEX(_xlfn.TEXTSPLIT(AO74,",",),0,2)+$A$18,$A$18)=0,$A$18,MOD(AO$18+INDEX(_xlfn.TEXTSPLIT(AO74,",",),0,2)+$A$18,$A$18))/4,0)))+(INDEX($AD$2:$AK$9,ROUNDUP($A19/5,0),ROUNDUP(IF(MOD(AO$18+INDEX(_xlfn.TEXTSPLIT(AO117,",",),0,2)+$A$18,$A$18)=0,$A$18,MOD(AO$18+INDEX(_xlfn.TEXTSPLIT(AO117,",",),0,2)+$A$18,$A$18))/5,0)))} -> 2
A20: 2 | B20: {=(INDEX($K$2:$T$11,ROUNDUP(IF(MOD($A20+INDEX(_xlfn.TEXTSPLIT(B75,",",),0,1)+$A$18,$A$18)=0,$A$18,MOD($A20+INDEX(_xlfn.TEXTSPLIT(B75,",",),0,1)+$A$18,$A$18))/4,0),ROUNDUP(IF(MOD(B$18+INDEX(_xlfn.TEXTSPLIT(B75,",",),0,2)+$A$18,$A$18)=0,$A$18,MOD(B$18+INDEX(_xlfn.TEXTSPLIT(B75,",",),0,2)+$A$18,$A$18))/4,0)))+(INDEX($AD$2:$AK$9,ROUNDUP(IF(MOD($A20+INDEX(_xlfn.TEXTSPLIT(B118,",",),0,1)+$A$18,$A$18)=0,$A$18,MOD($A20+INDEX(_xlfn.TEXTSPLIT(B118,",",),0,1)+$A$18,$A$18))/5,0),ROUNDUP(IF(MOD(B$18+INDEX(_xlfn.TEXTSPLIT(B118,",",),0,2)+$A$18,$A$18)=0,$A$18,MOD(B$18+INDEX(_xlfn.TEXTSPLIT(B118,",",),0,2)+$A$18,$A$18))/5,0)))} -> 2 | C20: {=(INDEX($K$2:$T$11,ROUNDUP(IF(MOD($A20+INDEX(_xlfn.TEXTSPLIT(C75,",",),0,1)+$A$18,$A$18)=0,$A$18,MOD($A20+INDEX(_xlfn.TEXTSPLIT(C75,",",),0,1)+$A$18,$A$18))/4,0),ROUNDUP(IF(MOD(C$18+INDEX(_xlfn.TEXTSPLIT(C75,",",),0,2)+$A$18,$A$18)=0,$A$18,MOD(C$18+INDEX(_xlfn.TEXTSPLIT(C75,",",),0,2)+$A$18,$A$18))/4,0)))+(INDEX($AD$2:$AK$9,ROUNDUP(IF(MOD($A20+INDEX(_xlfn.TEXTSPLIT(C118,",",),0,1)+$A$18,$A$18)=0,$A$18,MOD($A20+INDEX(_xlfn.TEXTSPLIT(C118,",",),0,1)+$A$18,$A$18))/5,0),ROUNDUP(IF(MOD(C$18+INDEX(_xlfn.TEXTSPLIT(C118,",",),0,2)+$A$18,$A$18)=0,$A$18,MOD(C$18+INDEX(_xlfn.TEXTSPLIT(C118,",",),0,2)+$A$18,$A$18))/5,0)))} -> 2 | D20: {=(INDEX($K$2:$T$11,ROUNDUP(IF(MOD($A20+INDEX(_xlfn.TEXTSPLIT(D75,",",),0,1)+$A$18,$A$18)=0,$A$18,MOD($A20+INDEX(_xlfn.TEXTSPLIT(D75,",",),0,1)+$A$18,$A$18))/4,0),ROUNDUP(IF(MOD(D$18+INDEX(_xlfn.TEXTSPLIT(D75,",",),0,2)+$A$18,$A$18)=0,$A$18,MOD(D$18+INDEX(_xlfn.TEXTSPLIT(D75,",",),0,2)+$A$18,$A$18))/4,0)))+(INDEX($AD$2:$AK$9,ROUNDUP(IF(MOD($A20+INDEX(_xlfn.TEXTSPLIT(D118,",",),0,1)+$A$18,$A$18)=0,$A$18,MOD($A20+INDEX(_xlfn.TEXTSPLIT(D118,",",),0,1)+$A$18,$A$18))/5,0),ROUNDUP(IF(MOD(D$18+INDEX(_xlfn.TEXTSPLIT(D118,",",),0,2)+$A$18,$A$18)=0,$A$18,MOD(D$18+INDEX(_xlfn.TEXTSPLIT(D118,",",),0,2)+$A$18,$A$18))/5,0)))} -> 2 | E20: {=(INDEX($K$2:$T$11,ROUNDUP(IF(MOD($A20+INDEX(_xlfn.TEXTSPLIT(E75,",",),0,1)+$A$18,$A$18)=0,$A$18,MOD($A20+INDEX(_xlfn.TEXTSPLIT(E75,",",),0,1)+$A$18,$A$18))/4,0),ROUNDUP(IF(MOD(E$18+INDEX(_xlfn.TEXTSPLIT(E75,",",),0,2)+$A$18,$A$18)=0,$A$18,MOD(E$18+INDEX(_xlfn.TEXTSPLIT(E75,",",),0,2)+$A$18,$A$18))/4,0)))+(INDEX($AD$2:$AK$9,ROUNDUP(IF(MOD($A20+INDEX(_xlfn.TEXTSPLIT(E118,",",),0,1)+$A$18,$A$18)=0,$A$18,MOD($A20+INDEX(_xlfn.TEXTSPLIT(E118,",",),0,1)+$A$18,$A$18))/5,0),ROUNDUP(IF(MOD(E$18+INDEX(_xlfn.TEXTSPLIT(E118,",",),0,2)+$A$18,$A$18)=0,$A$18,MOD(E$18+INDEX(_xlfn.TEXTSPLIT(E118,",",),0,2)+$A$18,$A$18))/5,0)))} -> 2 | F20: {=(INDEX($K$2:$T$11,ROUNDUP(IF(MOD($A20+INDEX(_xlfn.TEXTSPLIT(F75,",",),0,1)+$A$18,$A$18)=0,$A$18,MOD($A20+INDEX(_xlfn.TEXTSPLIT(F75,",",),0,1)+$A$18,$A$18))/4,0),ROUNDUP(IF(MOD(F$18+INDEX(_xlfn.TEXTSPLIT(F75,",",),0,2)+$A$18,$A$18)=0,$A$18,MOD(F$18+INDEX(_xlfn.TEXTSPLIT(F75,",",),0,2)+$A$18,$A$18))/4,0)))+(INDEX($AD$2:$AK$9,ROUNDUP(IF(MOD($A20+INDEX(_xlfn.TEXTSPLIT(F118,",",),0,1)+$A$18,$A$18)=0,$A$18,MOD($A20+INDEX(_xlfn.TEXTSPLIT(F118,",",),0,1)+$A$18,$A$18))/5,0),ROUNDUP(IF(MOD(F$18+INDEX(_xlfn.TEXTSPLIT(F118,",",),0,2)+$A$18,$A$18)=0,$A$18,MOD(F$18+INDEX(_xlfn.TEXTSPLIT(F118,",",),0,2)+$A$18,$A$18))/5,0)))} -> 2 | G20: {=(INDEX($K$2:$T$11,ROUNDUP(IF(MOD($A20+INDEX(_xlfn.TEXTSPLIT(G75,",",),0,1)+$A$18,$A$18)=0,$A$18,MOD($A20+INDEX(_xlfn.TEXTSPLIT(G75,",",),0,1)+$A$18,$A$18))/4,0),ROUNDUP(IF(MOD(G$18+INDEX(_xlfn.TEXTSPLIT(G75,",",),0,2)+$A$18,$A$18)=0,$A$18,MOD(G$18+INDEX(_xlfn.TEXTSPLIT(G75,",",),0,2)+$A$18,$A$18))/4,0)))+(INDEX($AD$2:$AK$9,ROUNDUP(IF(MOD($A20+INDEX(_xlfn.TEXTSPLIT(G118,",",),0,1)+$A$18,$A$18)=0,$A$18,MOD($A20+INDEX(_xlfn.TEXTSPLIT(G118,",",),0,1)+$A$18,$A$18))/5,0),ROUNDUP(IF(MOD(G$18+INDEX(_xlfn.TEXTSPLIT(G118,",",),0,2)+$A$18,$A$18)=0,$A$18,MOD(G$18+INDEX(_xlfn.TEXTSPLIT(G118,",",),0,2)+$A$18,$A$18))/5,0)))} -> 5 | H20: {=(INDEX($K$2:$T$11,ROUNDUP(IF(MOD($A20+INDEX(_xlfn.TEXTSPLIT(H75,",",),0,1)+$A$18,$A$18)=0,$A$18,MOD($A20+INDEX(_xlfn.TEXTSPLIT(H75,",",),0,1)+$A$18,$A$18))/4,0),ROUNDUP(IF(MOD(H$18+INDEX(_xlfn.TEXTSPLIT(H75,",",),0,2)+$A$18,$A$18)=0,$A$18,MOD(H$18+INDEX(_xlfn.TEXTSPLIT(H75,",",),0,2)+$A$18,$A$18))/4,0)))+(INDEX($AD$2:$AK$9,ROUNDUP(IF(MOD($A20+INDEX(_xlfn.TEXTSPLIT(H118,",",),0,1)+$A$18,$A$18)=0,$A$18,MOD($A20+INDEX(_xlfn.TEXTSPLIT(H118,",",),0,1)+$A$18,$A$18))/5,0),ROUNDUP(IF(MOD(H$18+INDEX(_xlfn.TEXTSPLIT(H118,",",),0,2)+$A$18,$A$18)=0,$A$18,MOD(H$18+INDEX(_xlfn.TEXTSPLIT(H118,",",),0,2)+$A$18,$A$18))/5,0)))} -> 5 | I20: {=(INDEX($K$2:$T$11,ROUNDUP(IF(MOD($A20+INDEX(_xlfn.TEXTSPLIT(I75,",",),0,1)+$A$18,$A$18)=0,$A$18,MOD($A20+INDEX(_xlfn.TEXTSPLIT(I75,",",),0,1)+$A$18,$A$18))/4,0),ROUNDUP(IF(MOD(I$18+INDEX(_xlfn.TEXTSPLIT(I75,",",),0,2)+$A$18,$A$18)=0,$A$18,MOD(I$18+INDEX(_xlfn.TEXTSPLIT(I75,",",),0,2)+$A$18,$A$18))/4,0)))+(INDEX($AD$2:$AK$9,ROUNDUP(IF(MOD($A20+INDEX(_xlfn.TEXTSPLIT(I118,",",),0,1)+$A$18,$A$18)=0,$A$18,MOD($A20+INDEX(_xlfn.TEXTSPLIT(I118,",",),0,1)+$A$18,$A$18))/5,0),ROUNDUP(IF(MOD(I$18+INDEX(_xlfn.TEXTSPLIT(I118,",",),0,2)+$A$18,$A$18)=0,$A$18,MOD(I$18+INDEX(_xlfn.TEXTSPLIT(I118,",",),0,2)+$A$18,$A$18))/5,0)))} -> 5 | ... AO20: {=(INDEX($K$2:$T$11,ROUNDUP(IF(MOD($A20+INDEX(_xlfn.TEXTSPLIT(AO75,",",),0,1)+$A$18,$A$18)=0,$A$18,MOD($A20+INDEX(_xlfn.TEXTSPLIT(AO75,",",),0,1)+$A$18,$A$18))/4,0),ROUNDUP(IF(MOD(AO$18+INDEX(_xlfn.TEXTSPLIT(AO75,",",),0,2)+$A$18,$A$18)=0,$A$18,MOD(AO$18+INDEX(_xlfn.TEXTSPLIT(AO75,",",),0,2)+$A$18,$A$18))/4,0)))+(INDEX($AD$2:$AK$9,ROUNDUP(IF(MOD($A20+INDEX(_xlfn.TEXTSPLIT(AO118,",",),0,1)+$A$18,$A$18)=0,$A$18,MOD($A20+INDEX(_xlfn.TEXTSPLIT(AO118,",",),0,1)+$A$18,$A$18))/5,0),ROUNDUP(IF(MOD(AO$18+INDEX(_xlfn.TEXTSPLIT(AO118,",",),0,2)+$A$18,$A$18)=0,$A$18,MOD(AO$18+INDEX(_xlfn.TEXTSPLIT(AO118,",",),0,2)+$A$18,$A$18))/5,0)))} -> 2
